Workbook
Name ak: #REF!
Name ap: #REF!

Sheet summary
B2: [ oo팀 재고 현황 ]
B4: 구분 | D4: 자사물류 | F4: 날개물류 | H4: MQ물류 | J4: 볼드나인물류 | L4: SH물류
D5: 전월 | E5: 당월 | F5: 전월 | G5: 당월 | H5: 전월 | I5: 당월 | J5: 전월 | K5: 당월 | L5: 전월 | M5: 당월
B6: 정상재고 | C6: SKU | E6: =COUNTIF(자사!$J:$J,summary!$B6) -> 40 | G6: =COUNTIF(날개!$J:$J,summary!$B6) -> 40 | I6: =COUNTIF(MQ!$J:$J,summary!$B6) -> 40 | K6: =COUNTIF('대화물류(이천)'!$J:$J,summary!$B6) -> 40 | M6: =COUNTIF(SH!$J:$J,summary!$B6) -> 40
C7: 수량 | E7: =SUMIF(자사!$J:$J,summary!$B6,자사!$H:$H) -> 0 | G7: =SUMIF(날개!$J:$J,summary!$B6,날개!$H:$H) -> 0 | I7: =SUMIF(MQ!$J:$J,summary!$B6,MQ!$H:$H) -> 0 | K7: =SUMIF('대화물류(이천)'!$J:$J,summary!$B6,'대화물류(이천)'!$H:$H) -> 0 | M7: =SUMIF(SH!$J:$J,summary!$B6,SH!$H:$H) -> 0
C8: % | D8: =+D7/D$16 -> #DIV/0! | E8: =+E7/E$16 -> #DIV/0! | F8: =+F7/F$16 -> #DIV/0! | G8: =+G7/G$16 -> #DIV/0! | H8: =+H7/H$16 -> #DIV/0! | I8: =+I7/I$16 -> #DIV/0! | J8: =+J7/J$16 -> #DIV/0! | K8: =+K7/K$16 -> #DIV/0! | ... M8: =+M7/M$16 -> #DIV/0!
B9: 부진재고 | C9: SKU | E9: =COUNTIF(자사!$J:$J,summary!$B9) -> 0 | G9: =COUNTIF(날개!$J:$J,summary!$B9) -> 0 | I9: =COUNTIF(MQ!$J:$J,summary!$B9) -> 0 | K9: =COUNTIF('대화물류(이천)'!$J:$J,summary!$B9) -> 0 | M9: =COUNTIF(SH!$J:$J,summary!$B9) -> 0
C10: 수량 | E10: =SUMIF(자사!$J:$J,summary!$B9,자사!$H:$H) -> 0 | G10: =SUMIF(날개!$J:$J,summary!$B9,날개!$H:$H) -> 0 | I10: =SUMIF(MQ!$J:$J,summary!$B9,MQ!$H:$H) -> 0 | K10: =SUMIF('대화물류(이천)'!$J:$J,summary!$B9,'대화물류(이천)'!$H:$H) -> 0 | M10: =SUMIF(SH!$J:$J,summary!$B9,SH!$H:$H) -> 0
C11: % | D11: =+D10/D$16 -> #DIV/0! | E11: =+E10/E$16 -> #DIV/0! | F11: =+F10/F$16 -> #DIV/0! | G11: =+G10/G$16 -> #DIV/0! | H11: =+H10/H$16 -> #DIV/0! | I11: =+I10/I$16 -> #DIV/0! | J11: =+J10/J$16 -> #DIV/0! | K11: =+K10/K$16 -> #DIV/0! | ... M11: =+M10/M$16 -> #DIV/0!
B12: 악성재고 | C12: SKU | E12: =COUNTIF(자사!$J:$J,summary!$B12) -> 0 | G12: =COUNTIF(날개!$J:$J,summary!$B12) -> 0 | I12: =COUNTIF(MQ!$J:$J,summary!$B12) -> 0 | K12: =COUNTIF('대화물류(이천)'!$J:$J,summary!$B12) -> 0 | M12: =COUNTIF(SH!$J:$J,summary!$B12) -> 0
C13: 수량 | E13: =SUMIF(자사!$J:$J,summary!$B12,자사!$H:$H) -> 0 | G13: =SUMIF(날개!$J:$J,summary!$B12,날개!$H:$H) -> 0 | I13: =SUMIF(MQ!$J:$J,summary!$B12,MQ!$H:$H) -> 0 | K13: =SUMIF('대화물류(이천)'!$J:$J,summary!$B12,'대화물류(이천)'!$H:$H) -> 0 | M13: =SUMIF(SH!$J:$J,summary!$B12,SH!$H:$H) -> 0
C14: % | D14: =+D13/D$16 -> #DIV/0! | E14: =+E13/E$16 -> #DIV/0! | F14: =+F13/F$16 -> #DIV/0! | G14: =+G13/G$16 -> #DIV/0! | H14: =+H13/H$16 -> #DIV/0! | I14: =+I13/I$16 -> #DIV/0! | J14: =+J13/J$16 -> #DIV/0! | K14: =+K13/K$16 -> #DIV/0! | ... M14: =+M13/M$16 -> #DIV/0!
B15: 계 | C15: SKU | D15: =+D6+D9+D12 -> 0 | E15: =+E6+E9+E12 -> 40 | F15: =+F6+F9+F12 -> 0 | G15: =+G6+G9+G12 -> 40 | H15: =+H6+H9+H12 -> 0 | I15: =+I6+I9+I12 -> 40 | J15: =+J6+J9+J12 -> 0 | K15: =+K6+K9+K12 -> 40 | ... M15: =+M6+M9+M12 -> 40
C16: 수량 | D16: =+D7+D10+D13 -> 0 | E16: =+E7+E10+E13 -> 0 | F16: =+F7+F10+F13 -> 0 | G16: =+G7+G10+G13 -> 0 | H16: =+H7+H10+H13 -> 0 | I16: =+I7+I10+I13 -> 0 | J16: =+J7+J10+J13 -> 0 | K16: =+K7+K10+K13 -> 0 | ... M16: =+M7+M10+M13 -> 0
C17: % | D17: =+D8+D11+D14 -> #DIV/0! | E17: =+E8+E11+E14 -> #DIV/0! | F17: =+F8+F11+F14 -> #DIV/0! | G17: =+G8+G11+G14 -> #DIV/0! | H17: =+H8+H11+H14 -> #DIV/0! | I17: =+I8+I11+I14 -> #DIV/0! | J17: =+J8+J11+J14 -> #DIV/0! | K17: =+K8+K11+K14 -> #DIV/0! | ... M17: =+M8+M11+M14 -> #DIV/0!

Sheet 자사
B2: [oo팀 자사물류 재고 현황 ]
B4: S | C4: 품목 | D4: 품목명 | E4: 기초재고 | F4: 입고량 | G4: 출고량 | H4: 기말재고 | I4: 재고회전율 | J4: 재고등급(사업부) | K4: 재고등급(경영지원) | L4: 비고
B5: 1 | I5: =IFERROR(IF(ROUND(G5/((E5+H5)/2),1)<0,0,ROUND(G5/((E5+H5)/2),1)),0) -> 0 | J5: =IF(OR(E5=0,H5=0,I5>1),"정상재고",IF(I5<0.5,"악성재고","부진재고")) -> 정상재고 | K5: =IFERROR(VLOOKUP(C5,재고자산수불부_26.09!$B$9:$BJ$3136,61,FALSE),"")
B6: 2 | I6: =IFERROR(IF(ROUND(G6/((E6+H6)/2),1)<0,0,ROUND(G6/((E6+H6)/2),1)),0) -> 0 | J6: =IF(OR(E6=0,H6=0,I6>1),"정상재고",IF(I6<0.5,"악성재고","부진재고")) -> 정상재고 | K6: =IFERROR(VLOOKUP(C6,재고자산수불부_26.09!$B$9:$BJ$3136,61,FALSE),"")
B7: 3 | I7: =IFERROR(IF(ROUND(G7/((E7+H7)/2),1)<0,0,ROUND(G7/((E7+H7)/2),1)),0) -> 0 | J7: =IF(OR(E7=0,H7=0,I7>1),"정상재고",IF(I7<0.5,"악성재고","부진재고")) -> 정상재고 | K7: =IFERROR(VLOOKUP(C7,재고자산수불부_26.09!$B$9:$BJ$3136,61,FALSE),"")
B8: 4 | I8: =IFERROR(IF(ROUND(G8/((E8+H8)/2),1)<0,0,ROUND(G8/((E8+H8)/2),1)),0) -> 0 | J8: =IF(OR(E8=0,H8=0,I8>1),"정상재고",IF(I8<0.5,"악성재고","부진재고")) -> 정상재고 | K8: =IFERROR(VLOOKUP(C8,재고자산수불부_26.09!$B$9:$BJ$3136,61,FALSE),"")
B9: 5 | I9: =IFERROR(IF(ROUND(G9/((E9+H9)/2),1)<0,0,ROUND(G9/((E9+H9)/2),1)),0) -> 0 | J9: =IF(OR(E9=0,H9=0,I9>1),"정상재고",IF(I9<0.5,"악성재고","부진재고")) -> 정상재고 | K9: =IFERROR(VLOOKUP(C9,재고자산수불부_26.09!$B$9:$BJ$3136,61,FALSE),"")
B10: 6 | I10: =IFERROR(IF(ROUND(G10/((E10+H10)/2),1)<0,0,ROUND(G10/((E10+H10)/2),1)),0) -> 0 | J10: =IF(OR(E10=0,H10=0,I10>1),"정상재고",IF(I10<0.5,"악성재고","부진재고")) -> 정상재고 | K10: =IFERROR(VLOOKUP(C10,재고자산수불부_26.09!$B$9:$BJ$3136,61,FALSE),"")
B11: 7 | I11: =IFERROR(IF(ROUND(G11/((E11+H11)/2),1)<0,0,ROUND(G11/((E11+H11)/2),1)),0) -> 0 | J11: =IF(OR(E11=0,H11=0,I11>1),"정상재고",IF(I11<0.5,"악성재고","부진재고")) -> 정상재고 | K11: =IFERROR(VLOOKUP(C11,재고자산수불부_26.09!$B$9:$BJ$3136,61,FALSE),"")
B12: 8 | I12: =IFERROR(IF(ROUND(G12/((E12+H12)/2),1)<0,0,ROUND(G12/((E12+H12)/2),1)),0) -> 0 | J12: =IF(OR(E12=0,H12=0,I12>1),"정상재고",IF(I12<0.5,"악성재고","부진재고")) -> 정상재고 | K12: =IFERROR(VLOOKUP(C12,재고자산수불부_26.09!$B$9:$BJ$3136,61,FALSE),"")
B13: 9 | I13: =IFERROR(IF(ROUND(G13/((E13+H13)/2),1)<0,0,ROUND(G13/((E13+H13)/2),1)),0) -> 0 | J13: =IF(OR(E13=0,H13=0,I13>1),"정상재고",IF(I13<0.5,"악성재고","부진재고")) -> 정상재고 | K13: =IFERROR(VLOOKUP(C13,재고자산수불부_26.09!$B$9:$BJ$3136,61,FALSE),"")
B14: 10 | I14: =IFERROR(IF(ROUND(G14/((E14+H14)/2),1)<0,0,ROUND(G14/((E14+H14)/2),1)),0) -> 0 | J14: =IF(OR(E14=0,H14=0,I14>1),"정상재고",IF(I14<0.5,"악성재고","부진재고")) -> 정상재고 | K14: =IFERROR(VLOOKUP(C14,재고자산수불부_26.09!$B$9:$BJ$3136,61,FALSE),"")
B15: 11 | I15: =IFERROR(IF(ROUND(G15/((E15+H15)/2),1)<0,0,ROUND(G15/((E15+H15)/2),1)),0) -> 0 | J15: =IF(OR(E15=0,H15=0,I15>1),"정상재고",IF(I15<0.5,"악성재고","부진재고")) -> 정상재고 | K15: =IFERROR(VLOOKUP(C15,재고자산수불부_26.09!$B$9:$BJ$3136,61,FALSE),"")
B16: 12 | I16: =IFERROR(IF(ROUND(G16/((E16+H16)/2),1)<0,0,ROUND(G16/((E16+H16)/2),1)),0) -> 0 | J16: =IF(OR(E16=0,H16=0,I16>1),"정상재고",IF(I16<0.5,"악성재고","부진재고")) -> 정상재고 | K16: =IFERROR(VLOOKUP(C16,재고자산수불부_26.09!$B$9:$BJ$3136,61,FALSE),"")
... B44: 40 | I44: =IFERROR(IF(ROUND(G44/((E44+H44)/2),1)<0,0,ROUND(G44/((E44+H44)/2),1)),0) -> 0 | J44: =IF(OR(E44=0,H44=0,I44>1),"정상재고",IF(I44<0.5,"악성재고","부진재고")) -> 정상재고 | K44: =IFERROR(VLOOKUP(C44,재고자산수불부_26.09!$B$9:$BJ$3136,61,FALSE),"")
B45: 계 | E45: =SUM(E5:E44) -> 0 | F45: =SUM(F5:F44) -> 0 | G45: =SUM(G5:G44) -> 0 | H45: =SUM(H5:H44) -> 0 | I45: =IFERROR(IF(ROUND(G45/((E45+H45)/2),1)<0,0,ROUND(G45/((E45+H45)/2),1)),0) -> 0

Sheet 날개
B2: [ oo팀 날개물류 재고 현황 ]
B4: S | C4: 품목 | D4: 품목명 | E4: 기초재고 | F4: 입고량 | G4: 출고량 | H4: 기말재고 | I4: 재고회전율 | J4: 재고등급 | K4: 재고등급(경영지원) | L4: 비고
B5: 1 | I5: =IFERROR(IF(ROUND(G5/((E5+H5)/2),1)<0,0,ROUND(G5/((E5+H5)/2),1)),0) -> 0 | J5: =IF(OR(E5=0,H5=0,I5>1),"정상재고",IF(I5<0.5,"악성재고","부진재고")) -> 정상재고 | K5: =IFERROR(VLOOKUP(C5,재고자산수불부_26.09!$B$9:$BJ$3136,61,FALSE),"")
B6: 2 | I6: =IFERROR(IF(ROUND(G6/((E6+H6)/2),1)<0,0,ROUND(G6/((E6+H6)/2),1)),0) -> 0 | J6: =IF(OR(E6=0,H6=0,I6>1),"정상재고",IF(I6<0.5,"악성재고","부진재고")) -> 정상재고 | K6: =IFERROR(VLOOKUP(C6,재고자산수불부_26.09!$B$9:$BJ$3136,61,FALSE),"")
B7: 3 | I7: =IFERROR(IF(ROUND(G7/((E7+H7)/2),1)<0,0,ROUND(G7/((E7+H7)/2),1)),0) -> 0 | J7: =IF(OR(E7=0,H7=0,I7>1),"정상재고",IF(I7<0.5,"악성재고","부진재고")) -> 정상재고 | K7: =IFERROR(VLOOKUP(C7,재고자산수불부_26.09!$B$9:$BJ$3136,61,FALSE),"")
B8: 4 | I8: =IFERROR(IF(ROUND(G8/((E8+H8)/2),1)<0,0,ROUND(G8/((E8+H8)/2),1)),0) -> 0 | J8: =IF(OR(E8=0,H8=0,I8>1),"정상재고",IF(I8<0.5,"악성재고","부진재고")) -> 정상재고 | K8: =IFERROR(VLOOKUP(C8,재고자산수불부_26.09!$B$9:$BJ$3136,61,FALSE),"")
B9: 5 | I9: =IFERROR(IF(ROUND(G9/((E9+H9)/2),1)<0,0,ROUND(G9/((E9+H9)/2),1)),0) -> 0 | J9: =IF(OR(E9=0,H9=0,I9>1),"정상재고",IF(I9<0.5,"악성재고","부진재고")) -> 정상재고 | K9: =IFERROR(VLOOKUP(C9,재고자산수불부_26.09!$B$9:$BJ$3136,61,FALSE),"")
B10: 6 | I10: =IFERROR(IF(ROUND(G10/((E10+H10)/2),1)<0,0,ROUND(G10/((E10+H10)/2),1)),0) -> 0 | J10: =IF(OR(E10=0,H10=0,I10>1),"정상재고",IF(I10<0.5,"악성재고","부진재고")) -> 정상재고 | K10: =IFERROR(VLOOKUP(C10,재고자산수불부_26.09!$B$9:$BJ$3136,61,FALSE),"")
B11: 7 | I11: =IFERROR(IF(ROUND(G11/((E11+H11)/2),1)<0,0,ROUND(G11/((E11+H11)/2),1)),0) -> 0 | J11: =IF(OR(E11=0,H11=0,I11>1),"정상재고",IF(I11<0.5,"악성재고","부진재고")) -> 정상재고 | K11: =IFERROR(VLOOKUP(C11,재고자산수불부_26.09!$B$9:$BJ$3136,61,FALSE),"")
B12: 8 | I12: =IFERROR(IF(ROUND(G12/((E12+H12)/2),1)<0,0,ROUND(G12/((E12+H12)/2),1)),0) -> 0 | J12: =IF(OR(E12=0,H12=0,I12>1),"정상재고",IF(I12<0.5,"악성재고","부진재고")) -> 정상재고 | K12: =IFERROR(VLOOKUP(C12,재고자산수불부_26.09!$B$9:$BJ$3136,61,FALSE),"")
B13: 9 | I13: =IFERROR(IF(ROUND(G13/((E13+H13)/2),1)<0,0,ROUND(G13/((E13+H13)/2),1)),0) -> 0 | J13: =IF(OR(E13=0,H13=0,I13>1),"정상재고",IF(I13<0.5,"악성재고","부진재고")) -> 정상재고 | K13: =IFERROR(VLOOKUP(C13,재고자산수불부_26.09!$B$9:$BJ$3136,61,FALSE),"")
B14: 10 | I14: =IFERROR(IF(ROUND(G14/((E14+H14)/2),1)<0,0,ROUND(G14/((E14+H14)/2),1)),0) -> 0 | J14: =IF(OR(E14=0,H14=0,I14>1),"정상재고",IF(I14<0.5,"악성재고","부진재고")) -> 정상재고 | K14: =IFERROR(VLOOKUP(C14,재고자산수불부_26.09!$B$9:$BJ$3136,61,FALSE),"")
B15: 11 | I15: =IFERROR(IF(ROUND(G15/((E15+H15)/2),1)<0,0,ROUND(G15/((E15+H15)/2),1)),0) -> 0 | J15: =IF(OR(E15=0,H15=0,I15>1),"정상재고",IF(I15<0.5,"악성재고","부진재고")) -> 정상재고 | K15: =IFERROR(VLOOKUP(C15,재고자산수불부_26.09!$B$9:$BJ$3136,61,FALSE),"")
B16: 12 | I16: =IFERROR(IF(ROUND(G16/((E16+H16)/2),1)<0,0,ROUND(G16/((E16+H16)/2),1)),0) -> 0 | J16: =IF(OR(E16=0,H16=0,I16>1),"정상재고",IF(I16<0.5,"악성재고","부진재고")) -> 정상재고 | K16: =IFERROR(VLOOKUP(C16,재고자산수불부_26.09!$B$9:$BJ$3136,61,FALSE),"")
... B44: 40 | I44: =IFERROR(IF(ROUND(G44/((E44+H44)/2),1)<0,0,ROUND(G44/((E44+H44)/2),1)),0) -> 0 | J44: =IF(OR(E44=0,H44=0,I44>1),"정상재고",IF(I44<0.5,"악성재고","부진재고")) -> 정상재고 | K44: =IFERROR(VLOOKUP(C44,재고자산수불부_26.09!$B$9:$BJ$3136,61,FALSE),"")
B45: 계 | E45: =SUM(E5:E44) -> 0 | F45: =SUM(F5:F44) -> 0 | G45: =SUM(G5:G44) -> 0 | H45: =SUM(H5:H44) -> 0 | I45: =IFERROR(IF(ROUND(G45/((E45+H45)/2),1)<0,0,ROUND(G45/((E45+H45)/2),1)),0) -> 0

Sheet MQ
B2: [ oo팀 MQ 재고 현황 ]
B4: S | C4: 품목 | D4: 품목명 | E4: 기초재고 | F4: 입고량 | G4: 출고량 | H4: 기말재고 | I4: 재고회전율 | J4: 재고등급 | K4: 재고등급(경영지원) | L4: 비고
B5: 1 | I5: =IFERROR(IF(ROUND(G5/((E5+H5)/2),1)<0,0,ROUND(G5/((E5+H5)/2),1)),0) -> 0 | J5: =IF(OR(E5=0,H5=0,I5>1),"정상재고",IF(I5<0.5,"악성재고","부진재고")) -> 정상재고 | K5: =IFERROR(VLOOKUP(C5,재고자산수불부_26.09!$B$9:$BJ$3136,61,FALSE),"")
B6: 2 | I6: =IFERROR(IF(ROUND(G6/((E6+H6)/2),1)<0,0,ROUND(G6/((E6+H6)/2),1)),0) -> 0 | J6: =IF(OR(E6=0,H6=0,I6>1),"정상재고",IF(I6<0.5,"악성재고","부진재고")) -> 정상재고 | K6: =IFERROR(VLOOKUP(C6,재고자산수불부_26.09!$B$9:$BJ$3136,61,FALSE),"")
B7: 3 | I7: =IFERROR(IF(ROUND(G7/((E7+H7)/2),1)<0,0,ROUND(G7/((E7+H7)/2),1)),0) -> 0 | J7: =IF(OR(E7=0,H7=0,I7>1),"정상재고",IF(I7<0.5,"악성재고","부진재고")) -> 정상재고 | K7: =IFERROR(VLOOKUP(C7,재고자산수불부_26.09!$B$9:$BJ$3136,61,FALSE),"")
B8: 4 | I8: =IFERROR(IF(ROUND(G8/((E8+H8)/2),1)<0,0,ROUND(G8/((E8+H8)/2),1)),0) -> 0 | J8: =IF(OR(E8=0,H8=0,I8>1),"정상재고",IF(I8<0.5,"악성재고","부진재고")) -> 정상재고 | K8: =IFERROR(VLOOKUP(C8,재고자산수불부_26.09!$B$9:$BJ$3136,61,FALSE),"")
B9: 5 | I9: =IFERROR(IF(ROUND(G9/((E9+H9)/2),1)<0,0,ROUND(G9/((E9+H9)/2),1)),0) -> 0 | J9: =IF(OR(E9=0,H9=0,I9>1),"정상재고",IF(I9<0.5,"악성재고","부진재고")) -> 정상재고 | K9: =IFERROR(VLOOKUP(C9,재고자산수불부_26.09!$B$9:$BJ$3136,61,FALSE),"")
B10: 6 | I10: =IFERROR(IF(ROUND(G10/((E10+H10)/2),1)<0,0,ROUND(G10/((E10+H10)/2),1)),0) -> 0 | J10: =IF(OR(E10=0,H10=0,I10>1),"정상재고",IF(I10<0.5,"악성재고","부진재고")) -> 정상재고 | K10: =IFERROR(VLOOKUP(C10,재고자산수불부_26.09!$B$9:$BJ$3136,61,FALSE),"")
B11: 7 | I11: =IFERROR(IF(ROUND(G11/((E11+H11)/2),1)<0,0,ROUND(G11/((E11+H11)/2),1)),0) -> 0 | J11: =IF(OR(E11=0,H11=0,I11>1),"정상재고",IF(I11<0.5,"악성재고","부진재고")) -> 정상재고 | K11: =IFERROR(VLOOKUP(C11,재고자산수불부_26.09!$B$9:$BJ$3136,61,FALSE),"")
B12: 8 | I12: =IFERROR(IF(ROUND(G12/((E12+H12)/2),1)<0,0,ROUND(G12/((E12+H12)/2),1)),0) -> 0 | J12: =IF(OR(E12=0,H12=0,I12>1),"정상재고",IF(I12<0.5,"악성재고","부진재고")) -> 정상재고 | K12: =IFERROR(VLOOKUP(C12,재고자산수불부_26.09!$B$9:$BJ$3136,61,FALSE),"")
B13: 9 | I13: =IFERROR(IF(ROUND(G13/((E13+H13)/2),1)<0,0,ROUND(G13/((E13+H13)/2),1)),0) -> 0 | J13: =IF(OR(E13=0,H13=0,I13>1),"정상재고",IF(I13<0.5,"악성재고","부진재고")) -> 정상재고 | K13: =IFERROR(VLOOKUP(C13,재고자산수불부_26.09!$B$9:$BJ$3136,61,FALSE),"")
B14: 10 | I14: =IFERROR(IF(ROUND(G14/((E14+H14)/2),1)<0,0,ROUND(G14/((E14+H14)/2),1)),0) -> 0 | J14: =IF(OR(E14=0,H14=0,I14>1),"정상재고",IF(I14<0.5,"악성재고","부진재고")) -> 정상재고 | K14: =IFERROR(VLOOKUP(C14,재고자산수불부_26.09!$B$9:$BJ$3136,61,FALSE),"")
B15: 11 | I15: =IFERROR(IF(ROUND(G15/((E15+H15)/2),1)<0,0,ROUND(G15/((E15+H15)/2),1)),0) -> 0 | J15: =IF(OR(E15=0,H15=0,I15>1),"정상재고",IF(I15<0.5,"악성재고","부진재고")) -> 정상재고 | K15: =IFERROR(VLOOKUP(C15,재고자산수불부_26.09!$B$9:$BJ$3136,61,FALSE),"")
B16: 12 | I16: =IFERROR(IF(ROUND(G16/((E16+H16)/2),1)<0,0,ROUND(G16/((E16+H16)/2),1)),0) -> 0 | J16: =IF(OR(E16=0,H16=0,I16>1),"정상재고",IF(I16<0.5,"악성재고","부진재고")) -> 정상재고 | K16: =IFERROR(VLOOKUP(C16,재고자산수불부_26.09!$B$9:$BJ$3136,61,FALSE),"")
... B44: 40 | I44: =IFERROR(IF(ROUND(G44/((E44+H44)/2),1)<0,0,ROUND(G44/((E44+H44)/2),1)),0) -> 0 | J44: =IF(OR(E44=0,H44=0,I44>1),"정상재고",IF(I44<0.5,"악성재고","부진재고")) -> 정상재고 | K44: =IFERROR(VLOOKUP(C44,재고자산수불부_26.09!$B$9:$BJ$3136,61,FALSE),"")
B45: 계 | E45: =SUM(E5:E44) -> 0 | F45: =SUM(F5:F44) -> 0 | G45: =SUM(G5:G44) -> 0 | H45: =SUM(H5:H44) -> 0 | I45: =IFERROR(IF(ROUND(G45/((E45+H45)/2),1)<0,0,ROUND(G45/((E45+H45)/2),1)),0) -> 0

Sheet 대화물류(이천)
B2: [ oo팀 대화물류(이천) 재고 현황 ]
B4: S | C4: 품목 | D4: 품목명 | E4: 기초재고 | F4: 입고량 | G4: 출고량 | H4: 기말재고 | I4: 재고회전율 | J4: 재고등급 | K4: 재고등급(경영지원) | L4: 비고
B5: 1 | I5: =IFERROR(IF(ROUND(G5/((E5+H5)/2),1)<0,0,ROUND(G5/((E5+H5)/2),1)),0) -> 0 | J5: =IF(OR(E5=0,H5=0,I5>1),"정상재고",IF(I5<0.5,"악성재고","부진재고")) -> 정상재고 | K5: =IFERROR(VLOOKUP(C5,재고자산수불부_26.09!$B$9:$BJ$3136,61,FALSE),"")
B6: 2 | I6: =IFERROR(IF(ROUND(G6/((E6+H6)/2),1)<0,0,ROUND(G6/((E6+H6)/2),1)),0) -> 0 | J6: =IF(OR(E6=0,H6=0,I6>1),"정상재고",IF(I6<0.5,"악성재고","부진재고")) -> 정상재고 | K6: =IFERROR(VLOOKUP(C6,재고자산수불부_26.09!$B$9:$BJ$3136,61,FALSE),"")
B7: 3 | I7: =IFERROR(IF(ROUND(G7/((E7+H7)/2),1)<0,0,ROUND(G7/((E7+H7)/2),1)),0) -> 0 | J7: =IF(OR(E7=0,H7=0,I7>1),"정상재고",IF(I7<0.5,"악성재고","부진재고")) -> 정상재고 | K7: =IFERROR(VLOOKUP(C7,재고자산수불부_26.09!$B$9:$BJ$3136,61,FALSE),"")
B8: 4 | I8: =IFERROR(IF(ROUND(G8/((E8+H8)/2),1)<0,0,ROUND(G8/((E8+H8)/2),1)),0) -> 0 | J8: =IF(OR(E8=0,H8=0,I8>1),"정상재고",IF(I8<0.5,"악성재고","부진재고")) -> 정상재고 | K8: =IFERROR(VLOOKUP(C8,재고자산수불부_26.09!$B$9:$BJ$3136,61,FALSE),"")
B9: 5 | I9: =IFERROR(IF(ROUND(G9/((E9+H9)/2),1)<0,0,ROUND(G9/((E9+H9)/2),1)),0) -> 0 | J9: =IF(OR(E9=0,H9=0,I9>1),"정상재고",IF(I9<0.5,"악성재고","부진재고")) -> 정상재고 | K9: =IFERROR(VLOOKUP(C9,재고자산수불부_26.09!$B$9:$BJ$3136,61,FALSE),"")
B10: 6 | I10: =IFERROR(IF(ROUND(G10/((E10+H10)/2),1)<0,0,ROUND(G10/((E10+H10)/2),1)),0) -> 0 | J10: =IF(OR(E10=0,H10=0,I10>1),"정상재고",IF(I10<0.5,"악성재고","부진재고")) -> 정상재고 | K10: =IFERROR(VLOOKUP(C10,재고자산수불부_26.09!$B$9:$BJ$3136,61,FALSE),"")
B11: 7 | I11: =IFERROR(IF(ROUND(G11/((E11+H11)/2),1)<0,0,ROUND(G11/((E11+H11)/2),1)),0) -> 0 | J11: =IF(OR(E11=0,H11=0,I11>1),"정상재고",IF(I11<0.5,"악성재고","부진재고")) -> 정상재고 | K11: =IFERROR(VLOOKUP(C11,재고자산수불부_26.09!$B$9:$BJ$3136,61,FALSE),"")
B12: 8 | I12: =IFERROR(IF(ROUND(G12/((E12+H12)/2),1)<0,0,ROUND(G12/((E12+H12)/2),1)),0) -> 0 | J12: =IF(OR(E12=0,H12=0,I12>1),"정상재고",IF(I12<0.5,"악성재고","부진재고")) -> 정상재고 | K12: =IFERROR(VLOOKUP(C12,재고자산수불부_26.09!$B$9:$BJ$3136,61,FALSE),"")
B13: 9 | I13: =IFERROR(IF(ROUND(G13/((E13+H13)/2),1)<0,0,ROUND(G13/((E13+H13)/2),1)),0) -> 0 | J13: =IF(OR(E13=0,H13=0,I13>1),"정상재고",IF(I13<0.5,"악성재고","부진재고")) -> 정상재고 | K13: =IFERROR(VLOOKUP(C13,재고자산수불부_26.09!$B$9:$BJ$3136,61,FALSE),"")
B14: 10 | I14: =IFERROR(IF(ROUND(G14/((E14+H14)/2),1)<0,0,ROUND(G14/((E14+H14)/2),1)),0) -> 0 | J14: =IF(OR(E14=0,H14=0,I14>1),"정상재고",IF(I14<0.5,"악성재고","부진재고")) -> 정상재고 | K14: =IFERROR(VLOOKUP(C14,재고자산수불부_26.09!$B$9:$BJ$3136,61,FALSE),"")
B15: 11 | I15: =IFERROR(IF(ROUND(G15/((E15+H15)/2),1)<0,0,ROUND(G15/((E15+H15)/2),1)),0) -> 0 | J15: =IF(OR(E15=0,H15=0,I15>1),"정상재고",IF(I15<0.5,"악성재고","부진재고")) -> 정상재고 | K15: =IFERROR(VLOOKUP(C15,재고자산수불부_26.09!$B$9:$BJ$3136,61,FALSE),"")
B16: 12 | I16: =IFERROR(IF(ROUND(G16/((E16+H16)/2),1)<0,0,ROUND(G16/((E16+H16)/2),1)),0) -> 0 | J16: =IF(OR(E16=0,H16=0,I16>1),"정상재고",IF(I16<0.5,"악성재고","부진재고")) -> 정상재고 | K16: =IFERROR(VLOOKUP(C16,재고자산수불부_26.09!$B$9:$BJ$3136,61,FALSE),"")
... B44: 40 | I44: =IFERROR(IF(ROUND(G44/((E44+H44)/2),1)<0,0,ROUND(G44/((E44+H44)/2),1)),0) -> 0 | J44: =IF(OR(E44=0,H44=0,I44>1),"정상재고",IF(I44<0.5,"악성재고","부진재고")) -> 정상재고 | K44: =IFERROR(VLOOKUP(C44,재고자산수불부_26.09!$B$9:$BJ$3136,61,FALSE),"")
B45: 계 | E45: =SUM(E5:E44) -> 0 | F45: =SUM(F5:F44) -> 0 | G45: =SUM(G5:G44) -> 0 | H45: =SUM(H5:H44) -> 0 | I45: =IFERROR(IF(ROUND(G45/((E45+H45)/2),1)<0,0,ROUND(G45/((E45+H45)/2),1)),0) -> 0

Sheet SH
B2: [ oo팀 SH물류 재고 현황 ]
B4: S | C4: 품목 | D4: 품목명 | E4: 기초재고 | F4: 입고량 | G4: 출고량 | H4: 기말재고 | I4: 재고회전율 | J4: 재고등급 | K4: 재고등급(경영지원) | L4: 비고
B5: 1 | I5: =IFERROR(IF(ROUND(G5/((E5+H5)/2),1)<0,0,ROUND(G5/((E5+H5)/2),1)),0) -> 0 | J5: =IF(OR(E5=0,H5=0,I5>1),"정상재고",IF(I5<0.5,"악성재고","부진재고")) -> 정상재고 | K5: =IFERROR(VLOOKUP(C5,재고자산수불부_26.09!$B$9:$BJ$3136,61,FALSE),"")
B6: 2 | I6: =IFERROR(IF(ROUND(G6/((E6+H6)/2),1)<0,0,ROUND(G6/((E6+H6)/2),1)),0) -> 0 | J6: =IF(OR(E6=0,H6=0,I6>1),"정상재고",IF(I6<0.5,"악성재고","부진재고")) -> 정상재고 | K6: =IFERROR(VLOOKUP(C6,재고자산수불부_26.09!$B$9:$BJ$3136,61,FALSE),"")
B7: 3 | I7: =IFERROR(IF(ROUND(G7/((E7+H7)/2),1)<0,0,ROUND(G7/((E7+H7)/2),1)),0) -> 0 | J7: =IF(OR(E7=0,H7=0,I7>1),"정상재고",IF(I7<0.5,"악성재고","부진재고")) -> 정상재고 | K7: =IFERROR(VLOOKUP(C7,재고자산수불부_26.09!$B$9:$BJ$3136,61,FALSE),"")
B8: 4 | I8: =IFERROR(IF(ROUND(G8/((E8+H8)/2),1)<0,0,ROUND(G8/((E8+H8)/2),1)),0) -> 0 | J8: =IF(OR(E8=0,H8=0,I8>1),"정상재고",IF(I8<0.5,"악성재고","부진재고")) -> 정상재고 | K8: =IFERROR(VLOOKUP(C8,재고자산수불부_26.09!$B$9:$BJ$3136,61,FALSE),"")
B9: 5 | I9: =IFERROR(IF(ROUND(G9/((E9+H9)/2),1)<0,0,ROUND(G9/((E9+H9)/2),1)),0) -> 0 | J9: =IF(OR(E9=0,H9=0,I9>1),"정상재고",IF(I9<0.5,"악성재고","부진재고")) -> 정상재고 | K9: =IFERROR(VLOOKUP(C9,재고자산수불부_26.09!$B$9:$BJ$3136,61,FALSE),"")
B10: 6 | I10: =IFERROR(IF(ROUND(G10/((E10+H10)/2),1)<0,0,ROUND(G10/((E10+H10)/2),1)),0) -> 0 | J10: =IF(OR(E10=0,H10=0,I10>1),"정상재고",IF(I10<0.5,"악성재고","부진재고")) -> 정상재고 | K10: =IFERROR(VLOOKUP(C10,재고자산수불부_26.09!$B$9:$BJ$3136,61,FALSE),"")
B11: 7 | I11: =IFERROR(IF(ROUND(G11/((E11+H11)/2),1)<0,0,ROUND(G11/((E11+H11)/2),1)),0) -> 0 | J11: =IF(OR(E11=0,H11=0,I11>1),"정상재고",IF(I11<0.5,"악성재고","부진재고")) -> 정상재고 | K11: =IFERROR(VLOOKUP(C11,재고자산수불부_26.09!$B$9:$BJ$3136,61,FALSE),"")
B12: 8 | I12: =IFERROR(IF(ROUND(G12/((E12+H12)/2),1)<0,0,ROUND(G12/((E12+H12)/2),1)),0) -> 0 | J12: =IF(OR(E12=0,H12=0,I12>1),"정상재고",IF(I12<0.5,"악성재고","부진재고")) -> 정상재고 | K12: =IFERROR(VLOOKUP(C12,재고자산수불부_26.09!$B$9:$BJ$3136,61,FALSE),"")
B13: 9 | I13: =IFERROR(IF(ROUND(G13/((E13+H13)/2),1)<0,0,ROUND(G13/((E13+H13)/2),1)),0) -> 0 | J13: =IF(OR(E13=0,H13=0,I13>1),"정상재고",IF(I13<0.5,"악성재고","부진재고")) -> 정상재고 | K13: =IFERROR(VLOOKUP(C13,재고자산수불부_26.09!$B$9:$BJ$3136,61,FALSE),"")
B14: 10 | I14: =IFERROR(IF(ROUND(G14/((E14+H14)/2),1)<0,0,ROUND(G14/((E14+H14)/2),1)),0) -> 0 | J14: =IF(OR(E14=0,H14=0,I14>1),"정상재고",IF(I14<0.5,"악성재고","부진재고")) -> 정상재고 | K14: =IFERROR(VLOOKUP(C14,재고자산수불부_26.09!$B$9:$BJ$3136,61,FALSE),"")
B15: 11 | I15: =IFERROR(IF(ROUND(G15/((E15+H15)/2),1)<0,0,ROUND(G15/((E15+H15)/2),1)),0) -> 0 | J15: =IF(OR(E15=0,H15=0,I15>1),"정상재고",IF(I15<0.5,"악성재고","부진재고")) -> 정상재고 | K15: =IFERROR(VLOOKUP(C15,재고자산수불부_26.09!$B$9:$BJ$3136,61,FALSE),"")
B16: 12 | I16: =IFERROR(IF(ROUND(G16/((E16+H16)/2),1)<0,0,ROUND(G16/((E16+H16)/2),1)),0) -> 0 | J16: =IF(OR(E16=0,H16=0,I16>1),"정상재고",IF(I16<0.5,"악성재고","부진재고")) -> 정상재고 | K16: =IFERROR(VLOOKUP(C16,재고자산수불부_26.09!$B$9:$BJ$3136,61,FALSE),"")
... B44: 40 | I44: =IFERROR(IF(ROUND(G44/((E44+H44)/2),1)<0,0,ROUND(G44/((E44+H44)/2),1)),0) -> 0 | J44: =IF(OR(E44=0,H44=0,I44>1),"정상재고",IF(I44<0.5,"악성재고","부진재고")) -> 정상재고 | K44: =IFERROR(VLOOKUP(C44,재고자산수불부_26.09!$B$9:$BJ$3136,61,FALSE),"")
B45: 계 | E45: =SUM(E5:E44) -> 0 | F45: =SUM(F5:F44) -> 0 | G45: =SUM(G5:G44) -> 0 | H45: =SUM(H5:H44) -> 0 | I45: =IFERROR(IF(ROUND(G45/((E45+H45)/2),1)<0,0,ROUND(G45/((E45+H45)/2),1)),0) -> 0

Sheet 재고자산수불부_26.09
A1: 재 고 자 산 수 불 부 (2025년 04월 ~ 2026년 09월 현재) | AP1: 8429476789
A4: 제품 | D4: =D2012 -> 2489739 | E4: =E2012 -> 4858686 | F4: =F2012 -> 8429476789 | G4: =G2012 -> 347759946 | H4: =H2012 -> 3108856.2 | I4: =I2012 -> 127887588125 | J4: =J2012 -> 3949753 | K4: =K2012 -> 1122291.5 | ... V4: =V2012 -> 347118815 | X4: =X2012 -> 133134874013 | Y4: =Y2012 -> 300 | Z4: =Z2012 -> 4451.0933 | AA4: =AA2012 -> 1335328 | AB4: =AB2012 -> 6737811 | AD4: =AD2012 -> 1374451605 | AE4: =AE2012 -> 0 | AG4: =AG2012 -> 0 | AH4: =AH2012 -> 353856926 | AI4: =AI2012 -> 7196136.9 | AJ4: =AJ2012 -> 134510660946 | AK4: =AK2012 -> 6364531 | AL4: =AL2012 -> 5157603.5 | AM4: =AM2012 -> 10567013150 | AN4: =AM4+AJ4-U4-F4 -> 0 | AV4: =+ROUNDDOWN(AV5-AU6,-3) -> 0
A5: 상품 | D5: =D3136 -> 373786 | E5: =E3136 -> 0 | F5: =F3136 -> 1715031696 | G5: =G3136 -> 10229067 | H5: =H3136 -> 0 | I5: =I3136 -> 6188922728 | J5: =J3136 -> 0 | K5: =K3136 -> 0 | ... AM5: =AM3136 -> 2740500491 | AN5: =AM5+AJ5-U5-F5 -> 0 | AU5: =AM6-AU6 -> 0 | AV5: =+SUM(AV6:AZ6) -> 1.3307514e+10 | BG5: =AK6-BG6 -> 0 | KUS5: 52335
A6: 합 계 | D6: =SUM(D4:D5) -> 2863525 | E6: =SUM(E4:E5) -> 4858686 | F6: =SUM(F4:F5) -> 10144508485 | G6: =SUM(G4:G5) -> 357989013 | H6: =SUM(H4:H5) -> 3108856.2 | I6: =SUM(I4:I5) -> 134076510853 | J6: =SUM(J4:J5) -> 3949753 | K6: =SUM(K4:K5) -> 1122291.5 | ... AB6: =SUM(AB4:AB5) -> 15282365 | AC6: =SUBTOTAL(9,AC4:AC5) -> 0 | AD6: =SUM(AD4:AD5) -> 2330257876 | AE6: =SUM(AE4:AE5) -> 0 | AF6: =SUBTOTAL(9,AF4:AF5) -> 0 | AG6: =SUM(AG4:AG5) -> 0 | AH6: =SUM(AH4:AH5) -> 363842112 | AI6: =SUM(AI4:AI5) -> 7196136.9 | AJ6: =SUM(AJ4:AJ5) -> 139702871358 | AK6: =SUM(AK4:AK5) -> 6988255 | AL6: =SUM(AL4:AL5) -> 5157603.5 | AM6: =SUM(AM4:AM5) -> 13307513641 | AN6: =AM6+AJ6-U6-F6 -> 0 | AR6: =SUM(AR10:AR3136) -> 468226453 | AS6: =SUM(AS10:AS3136) -> 1994848735 | AT6: =SUM(AT10:AT3136) -> 10844438453 | AU6: =SUM(AU10:AU3136) -> 13307513641 | AV6: =SUM(AV10:AV3136) -> 1.2340393e+10 | AW6: =SUM(AW10:AW3136) -> 8.3268881e+08 | AX6: =SUM(AX10:AX3136) -> 8467073.5 | AY6: =SUM(AY10:AY3136) -> 1.2596465e+08 | AZ6: =SUM(AZ10:AZ3135) -> 0 | BB6: =SUM(BB10:BB3136) -> 4316976 | BC6: =SUM(BC10:BC3136) -> 2649289 | BD6: =SUM(BD10:BD3136) -> 1275 | BE6: =SUM(BE10:BE3136) -> 20715 | BF6: =SUM(BF10:BF3136) -> 0 | BG6: =SUM(BG10:BG3136) -> 6988255 | KUS6: 4726
A7: 품목계정 | D7: 기초재고 | G7: 입고 | H7: 입고 | I7: 입고 | J7: 입고 | K7: 입고 | L7: 입고 | M7: 입고 | N7: 입고 | O7: 입고 | S7: 입고 | T7: 입고 | U7: 입고 | V7: 출고 | W7: 출고 | X7: 출고 | Y7: 출고 | Z7: 출고 | AA7: 출고 | AE7: 출고 | AF7: 출고 | AG7: 출고 | AH7: 출고 | AI7: 출고 | AJ7: 출고 | AK7: 기말재고 | KUS7: =KUS5/KUS6 -> 11.073847 | KUT7: 3545 | KUU7: =KUS7*KUT7 -> 39256.787 | KUV7: =KUS5-KUU7 -> 13078.213
G8: 구매 | H8: 구매 | I8: 구매 | J8: 외주 | K8: 외주 | L8: 외주 | M8: 대체 | N8: 대체 | O8: 대체 | P8: 기타 | Q8: 대체 | R8: 대체 | S8: =15067013555/1000000 -> 15067.014 | T8: 합계 | U8: 합계 | V8: 매출 | W8: 매출 | X8: 매출 | Y8: 외주 | Z8: 외주 | AA8: 외주 | AB8: 대체 | AC8: 대체 | AD8: 대체 | AE8: 기타 | AF8: 대체 | AG8: 대체 | AH8: 합계 | AI8: 합계 | AJ8: 합계 | AR8: 재고금액 | AV8: 부서별 재고금액 | BB8: 부서별 수량
A9: 품목계정 | B9: 품목 | C9: 품목명 | D9: 수량 | E9: 단가 | F9: 금액 | G9: 수량 | H9: 단가 | I9: 금액 | J9: 수량 | K9: 단가 | L9: 금액 | M9: 수량 | N9: 단가 | O9: 금액 | P9: 수량 | Q9: 단가 | R9: 금액 | S9: 수량 | T9: 단가 | U9: 금액 | V9: 수량 | W9: 단가 | X9: 금액 | Y9: 수량 | Z9: 단가 | AA9: 금액 | AB9: 수량 | AC9: 단가 | AD9: 대체 | AE9: 수량 | AF9: 단가 | AG9: 대체 | AH9: 수량 | AI9: 단가 | AJ9: 금액 | AK9: 수량 | AL9: 단가 | AM9: 금액 | AN9: 비중 | AO9: 비율 | AP9: 구분1 | AQ9: 구분2 | AR9: 악성 | AS9: 부진 | AT9: 정상 | AU9: 합 계 | AV9: 영업본부 | AW9: 에프앤비본부 | AX9: 라이선스본부 | AY9: 미디어본부 | AZ9: MD개발본부 | BA9: 합 계 | BB9: 영업본부 | BC9: 에프앤비본부 | BD9: 라이선스본부 | BE9: 미디어본부 | BF9: MD개발본부 | BG9: 합 계 | BH9: 1 | BI9: 재고회전율 | BJ9: 구분 | BK9: 최종입고일 | BL9: 46295
A10: 제품 | B10: DCP123001 | C10: 데코데코 말캉말캉 종이 스퀴시 문구점 (구간) | D10: 490 | E10: 3278.9853 | F10: 1606702 | G10: 0 | H10: 0 | I10: 0 | J10: 6000 | K10: 3295.71 | L10: 19774260 | M10: 21 | N10: 156.85714 | O10: 3294 | P10: 0 | Q10: 0 | R10: 0 | S10: 6021 | T10: 3284.7623 | U10: 19777554 | V10: 4573 | W10: 3288.1537 | X10: 15036727 | Y10: 0 | Z10: 0 | AA10: 0 | AB10: 81 | AC10: 3286.1235 | AD10: 266176 | AE10: 0 | AF10: 0 | AG10: 0 | AH10: 4654 | AI10: 3288.1184 | AJ10: 15302903 | AK10: 1857 | AL10: 3274.8271 | AM10: 6081353 | AN10: =AM10/$AM$4 -> 0.0005755035 | AO10: =IF(ISERROR(AK10/(D10+S10)),,(AK10/(D10+S10))) -> 0.28520965 | AP10: 정상 | AQ10: =A10 -> 제품 | AR10: =IF($AP10="악성",$AM10,0) -> 0 | AS10: =IF($AP10="부진",$AM10,0) -> 0 | AT10: =IF($AP10="정상",$AM10,0) -> 6081353 | AU10: =SUM(AR10:AT10) -> 6081353 | AV10: =IF(+BB10*$AL10=0,"",+BB10*$AL10) -> 6081353.9 | AW10: =IF(+BC10*$AL10=0,"",+BC10*$AL10) | AX10: =IF(+BD10*$AL10=0,"",+BD10*$AL10) | AY10: =IF(+BE10*$AL10=0,"",+BE10*$AL10) | AZ10: =IF(+BF10*$AL10=0,"",+BF10*$AL10) | BB10: 1857 | BC10: 0 | BD10: 0 | BE10: 0 | BF10: 0 | BG10: =+SUM(BB10:BF10) -> 1857 | BH10: =BG10-AK10 -> 0 | BI10: =IFERROR(IF(ROUND(V10/((D10+AK10)/2),1)<0,0,ROUND(V10/((D10+AK10)/2),1)),0) -> 3.9 | BJ10: =IF(AK10=0,"정상",IF(AP10="악성","악성",IF(AND(BL10>3,BI10<0.5),"악성",IF(AND(AP10="정상",BL10<=3),"정상",IF(BI10>1,"정상","부진"))))) -> 정상 | BK10: 44958 | BL10: =DATEDIF(BK10,$BL$9,"m")+1 -> 44
A11: 제품 | B11: DCP123002 | C11: 데코데코 말캉말캉 슬라임 스퀴시 (구간) | D11: 402 | E11: 5682.6636 | F11: 2284430 | G11: 0 | H11: 0 | I11: 0 | J11: 4790 | K11: 5813.1152 | L11: 27844822 | M11: 0 | N11: 0 | O11: 0 | P11: 0 | Q11: 0 | R11: 0 | S11: 4790 | T11: 5813.1152 | U11: 27844822 | V11: 4370 | W11: 5801.6043 | X11: 25353011 | Y11: 0 | Z11: 0 | AA11: 0 | AB11: 18 | AC11: 5799.0556 | AD11: 104383 | AE11: 0 | AF11: 0 | AG11: 0 | AH11: 4388 | AI11: 5801.5939 | AJ11: 25457394 | AK11: 804 | AL11: 5810.7701 | AM11: 4671858 | AN11: =AM11/$AM$4 -> 0.00044211717 | AO11: =IF(ISERROR(AK11/(D11+S11)),,(AK11/(D11+S11))) -> 0.15485362 | AP11: 정상 | AQ11: =A11 -> 제품 | AR11: =IF($AP11="악성",$AM11,0) -> 0 | AS11: =IF($AP11="부진",$AM11,0) -> 0 | AT11: =IF($AP11="정상",$AM11,0) -> 4671858 | AU11: =SUM(AR11:AT11) -> 4671858 | AV11: =IF(+BB11*$AL11=0,"",+BB11*$AL11) -> 4671859.2 | AW11: =IF(+BC11*$AL11=0,"",+BC11*$AL11) | AX11: =IF(+BD11*$AL11=0,"",+BD11*$AL11) | AY11: =IF(+BE11*$AL11=0,"",+BE11*$AL11) | AZ11: =IF(+BF11*$AL11=0,"",+BF11*$AL11) | BB11: 804 | BC11: 0 | BD11: 0 | BE11: 0 | BF11: 0 | BG11: =+SUM(BB11:BF11) -> 804 | BH11: =BG11-AK11 -> 0 | BI11: =IFERROR(IF(ROUND(V11/((D11+AK11)/2),1)<0,0,ROUND(V11/((D11+AK11)/2),1)),0) -> 7.2 | BJ11: =IF(AK11=0,"정상",IF(AP11="악성","악성",IF(AND(BL11>3,BI11<0.5),"악성",IF(AND(AP11="정상",BL11<=3),"정상",IF(BI11>1,"정상","부진"))))) -> 정상 | BK11: 45108 | BL11: =DATEDIF(BK11,$BL$9,"m")+1 -> 39
A12: 제품 | B12: DCP123003 | C12: 데코데코 말캉말캉 토핑 스퀴시 (구간) | D12: 1881 | E12: 5398.0524 | F12: 10153735 | G12: 0 | H12: 0 | I12: 0 | J12: 1850 | K12: 5401.6568 | L12: 9993065 | M12: 0 | N12: 0 | O12: 0 | P12: 0 | Q12: 0 | R12: 0 | S12: 1850 | T12: 5401.6568 | U12: 9993065 | V12: 3711 | W12: 5399.8375 | X12: 20038797 | Y12: 0 | Z12: 0 | AA12: 0 | AB12: 12 | AC12: 5399.4167 | AD12: 64793 | AE12: 0 | AF12: 0 | AG12: 0 | AH12: 3723 | AI12: 5399.8362 | AJ12: 20103590 | AK12: 8 | AL12: 5401.3333 | AM12: 43210 | AN12: =AM12/$AM$4 -> 4.0891404e-06 | AO12: =IF(ISERROR(AK12/(D12+S12)),,(AK12/(D12+S12))) -> 0.0021441973 | AP12: 정상 | AQ12: =A12 -> 제품 | AR12: =IF($AP12="악성",$AM12,0) -> 0 | AS12: =IF($AP12="부진",$AM12,0) -> 0 | AT12: =IF($AP12="정상",$AM12,0) -> 43210 | AU12: =SUM(AR12:AT12) -> 43210 | AV12: =IF(+BB12*$AL12=0,"",+BB12*$AL12) -> 43210.666 | AW12: =IF(+BC12*$AL12=0,"",+BC12*$AL12) | AX12: =IF(+BD12*$AL12=0,"",+BD12*$AL12) | AY12: =IF(+BE12*$AL12=0,"",+BE12*$AL12) | AZ12: =IF(+BF12*$AL12=0,"",+BF12*$AL12) | BB12: 8 | BC12: 0 | BD12: 0 | BE12: 0 | BF12: 0 | BG12: =+SUM(BB12:BF12) -> 8 | BH12: =BG12-AK12 -> 0 | BI12: =IFERROR(IF(ROUND(V12/((D12+AK12)/2),1)<0,0,ROUND(V12/((D12+AK12)/2),1)),0) -> 3.9 | BJ12: =IF(AK12=0,"정상",IF(AP12="악성","악성",IF(AND(BL12>3,BI12<0.5),"악성",IF(AND(AP12="정상",BL12<=3),"정상",IF(BI12>1,"정상","부진"))))) -> 정상 | BK12: 46023 | BL12: =DATEDIF(BK12,$BL$9,"m")+1 -> 9
A13: 제품 | B13: DCP123004 | C13: 데코데코 말캉말캉 종이 스퀴시 편의점 | D13: 983 | E13: 3154.2157 | F13: 3100594 | G13: 0 | H13: 0 | I13: 0 | J13: 12000 | K13: 3177.46 | L13: 38129520 | M13: 153 | N13: 225.53595 | O13: 34507 | P13: 0 | Q13: 0 | R13: 0 | S13: 12153 | T13: 3140.2968 | U13: 38164027 | V13: 9816 | W13: 3129.6701 | X13: 30720842 | Y13: 0 | Z13: 0 | AA13: 0 | AB13: 47 | AC13: 3126.7447 | AD13: 146957 | AE13: 0 | AF13: 0 | AG13: 0 | AH13: 9863 | AI13: 3129.6562 | AJ13: 30867799 | AK13: 3273 | AL13: 3176.5423 | AM13: 10396822 | AN13: =AM13/$AM$4 -> 0.00098389411 | AO13: =IF(ISERROR(AK13/(D13+S13)),,(AK13/(D13+S13))) -> 0.24916261 | AP13: 정상 | AQ13: 제품 | AR13: =IF($AP13="악성",$AM13,0) -> 0 | AS13: =IF($AP13="부진",$AM13,0) -> 0 | AT13: =IF($AP13="정상",$AM13,0) -> 10396822 | AU13: =SUM(AR13:AT13) -> 10396822 | AV13: =IF(+BB13*$AL13=0,"",+BB13*$AL13) -> 10396823 | AW13: =IF(+BC13*$AL13=0,"",+BC13*$AL13) | AX13: =IF(+BD13*$AL13=0,"",+BD13*$AL13) | AY13: =IF(+BE13*$AL13=0,"",+BE13*$AL13) | AZ13: =IF(+BF13*$AL13=0,"",+BF13*$AL13) | BB13: 3273 | BC13: 0 | BD13: 0 | BE13: 0 | BF13: 0 | BG13: =+SUM(BB13:BF13) -> 3273 | BH13: =BG13-AK13 -> 0 | BI13: =IFERROR(IF(ROUND(V13/((D13+AK13)/2),1)<0,0,ROUND(V13/((D13+AK13)/2),1)),0) -> 4.6 | BJ13: =IF(AK13=0,"정상",IF(AP13="악성","악성",IF(AND(BL13>3,BI13<0.5),"악성",IF(AND(AP13="정상",BL13<=3),"정상",IF(BI13>1,"정상","부진"))))) -> 정상 | BK13: 46235 | BL13: =DATEDIF(BK13,$BL$9,"m")+1 -> 2
A14: 제품 | B14: DCP124001 | C14: 데코데코 매직글리터 - 솜인형 키링 만들기 | D14: 1888 | E14: 5387.7298 | F14: 10172033 | G14: 0 | H14: 0 | I14: 0 | J14: 0 | K14: 0 | L14: 0 | M14: 2 | N14: 5387.5 | O14: 10775 | P14: 0 | Q14: 0 | R14: 0 | S14: 2 | T14: 5387.5 | U14: 10775 | V14: 436 | W14: 5387.7477 | X14: 2349058 | Y14: 0 | Z14: 0 | AA14: 0 | AB14: 56 | AC14: 5387.8214 | AD14: 301718 | AE14: 0 | AF14: 0 | AG14: 0 | AH14: 492 | AI14: 5387.7561 | AJ14: 2650776 | AK14: 1398 | AL14: 5387.72 | AM14: 7532032 | AN14: =AM14/$AM$4 -> 0.00071278723 | AO14: =IF(ISERROR(AK14/(D14+S14)),,(AK14/(D14+S14))) -> 0.73968254 | AP14: 부진 | AQ14: 제품 | AR14: =IF($AP14="악성",$AM14,0) -> 0 | AS14: =IF($AP14="부진",$AM14,0) -> 7532032 | AT14: =IF($AP14="정상",$AM14,0) -> 0 | AU14: =SUM(AR14:AT14) -> 7532032 | AV14: =IF(+BB14*$AL14=0,"",+BB14*$AL14) -> 7532032.6 | AW14: =IF(+BC14*$AL14=0,"",+BC14*$AL14) | AX14: =IF(+BD14*$AL14=0,"",+BD14*$AL14) | AY14: =IF(+BE14*$AL14=0,"",+BE14*$AL14) | AZ14: =IF(+BF14*$AL14=0,"",+BF14*$AL14) | BB14: 1398 | BC14: 0 | BD14: 0 | BE14: 0 | BF14: 0 | BG14: =+SUM(BB14:BF14) -> 1398 | BH14: =BG14-AK14 -> 0 | BI14: =IFERROR(IF(ROUND(V14/((D14+AK14)/2),1)<0,0,ROUND(V14/((D14+AK14)/2),1)),0) -> 0.3 | BJ14: =IF(AK14=0,"정상",IF(AP14="악성","악성",IF(AND(BL14>3,BI14<0.5),"악성",IF(AND(AP14="정상",BL14<=3),"정상",IF(BI14>1,"정상","부진"))))) -> 악성 | BK14: 45292 | BL14: =DATEDIF(BK14,$BL$9,"m")+1 -> 33
A15: 제품 | B15: DCP124002 | C15: 데코데코 아이돌 메이크업 색칠북 | D15: 2368 | E15: 5795.5225 | F15: 13723797 | G15: 0 | H15: 0 | I15: 0 | J15: 0 | K15: 0 | L15: 0 | M15: 1 | N15: 5796 | O15: 5796 | P15: 0 | Q15: 0 | R15: 0 | S15: 1 | T15: 5796 | U15: 5796 | V15: 2340 | W15: 5795.5226 | X15: 13561523 | Y15: 0 | Z15: 0 | AA15: 0 | AB15: 21 | AC15: 5795.6667 | AD15: 121709 | AE15: 0 | AF15: 0 | AG15: 0 | AH15: 2361 | AI15: 5795.5239 | AJ15: 13683232 | AK15: 8 | AL15: 5795.2 | AM15: 46361 | AN15: =AM15/$AM$4 -> 4.3873325e-06 | AO15: =IF(ISERROR(AK15/(D15+S15)),,(AK15/(D15+S15))) -> 0.0033769523 | AP15: 부진 | AQ15: 제품 | AR15: =IF($AP15="악성",$AM15,0) -> 0 | AS15: =IF($AP15="부진",$AM15,0) -> 46361 | AT15: =IF($AP15="정상",$AM15,0) -> 0 | AU15: =SUM(AR15:AT15) -> 46361 | AV15: =IF(+BB15*$AL15=0,"",+BB15*$AL15) -> 46361.6 | AW15: =IF(+BC15*$AL15=0,"",+BC15*$AL15) | AX15: =IF(+BD15*$AL15=0,"",+BD15*$AL15) | AY15: =IF(+BE15*$AL15=0,"",+BE15*$AL15) | AZ15: =IF(+BF15*$AL15=0,"",+BF15*$AL15) | BB15: 8 | BC15: 0 | BD15: 0 | BE15: 0 | BF15: 0 | BG15: =+SUM(BB15:BF15) -> 8 | BH15: =BG15-AK15 -> 0 | BI15: =IFERROR(IF(ROUND(V15/((D15+AK15)/2),1)<0,0,ROUND(V15/((D15+AK15)/2),1)),0) -> 2 | BJ15: =IF(AK15=0,"정상",IF(AP15="악성","악성",IF(AND(BL15>3,BI15<0.5),"악성",IF(AND(AP15="정상",BL15<=3),"정상",IF(BI15>1,"정상","부진"))))) -> 정상 | BK15: 45413 | BL15: =DATEDIF(BK15,$BL$9,"m")+1 -> 29
A16: 제품 | B16: DCP124003 | C16: 데코데코 요요유니 슬라임 스퀴시 (플레이타임 전용) | D16: 0 | E16: 0 | F16: 0 | G16: 0 | H16: 0 | I16: 0 | J16: 3000 | K16: 5798.206 | L16: 17394618 | M16: 0 | N16: 0 | O16: 0 | P16: 0 | Q16: 0 | R16: 0 | S16: 3000 | T16: 5798.206 | U16: 17394618 | V16: 3000 | W16: 5798.206 | X16: 17394618 | Y16: 0 | Z16: 0 | AA16: 0 | AB16: 0 | AC16: 0 | AD16: 0 | AE16: 0 | AF16: 0 | AG16: 0 | AH16: 3000 | AI16: 5798.206 | AJ16: 17394618 | AK16: 0 | AL16: 0 | AM16: 0 | AN16: =AM16/$AM$4 -> 0 | AO16: =IF(ISERROR(AK16/(D16+S16)),,(AK16/(D16+S16))) -> 0 | AP16: 정상 | AQ16: 제품 | AR16: =IF($AP16="악성",$AM16,0) -> 0 | AS16: =IF($AP16="부진",$AM16,0) -> 0 | AT16: =IF($AP16="정상",$AM16,0) -> 0 | AU16: =SUM(AR16:AT16) -> 0 | AV16: =IF(+BB16*$AL16=0,"",+BB16*$AL16) | AW16: =IF(+BC16*$AL16=0,"",+BC16*$AL16) | AX16: =IF(+BD16*$AL16=0,"",+BD16*$AL16) | AY16: =IF(+BE16*$AL16=0,"",+BE16*$AL16) | AZ16: =IF(+BF16*$AL16=0,"",+BF16*$AL16) | BB16: 0 | BC16: 0 | BD16: 0 | BE16: 0 | BF16: 0 | BG16: =+SUM(BB16:BF16) -> 0 | BH16: =BG16-AK16 -> 0 | BI16: =IFERROR(IF(ROUND(V16/((D16+AK16)/2),1)<0,0,ROUND(V16/((D16+AK16)/2),1)),0) -> 0 | BJ16: =IF(AK16=0,"정상",IF(AP16="악성","악성",IF(AND(BL16>3,BI16<0.5),"악성",IF(AND(AP16="정상",BL16<=3),"정상",IF(BI16>1,"정상","부진"))))) -> 정상 | BK16: 45444 | BL16: =DATEDIF(BK16,$BL$9,"m")+1 -> 28
A17: 제품 | B17: DCP124004 | C17: 데코데코 미니 스퀴시 사장의 포용계 키트 | D17: 3148 | E17: 4496.5931 | F17: 14155275 | G17: 3000 | H17: 6455.5987 | I17: 19366796 | J17: 0 | K17: 0 | L17: 0 | M17: 0 | N17: 0 | O17: 0 | P17: 0 | Q17: 0 | R17: 0 | S17: 3000 | T17: 6455.5987 | U17: 19366796 | V17: 5743 | W17: 5415.8381 | X17: 31103158 | Y17: 0 | Z17: 0 | AA17: 0 | AB17: 202 | AC17: 5578.6436 | AD17: 1126886 | AE17: 0 | AF17: 0 | AG17: 0 | AH17: 5945 | AI17: 5421.3699 | AJ17: 32230044 | AK17: 203 | AL17: 6364.6695 | AM17: 1292027 | AN17: =AM17/$AM$4 -> 0.00012226984 | AO17: =IF(ISERROR(AK17/(D17+S17)),,(AK17/(D17+S17))) -> 0.033018868 | AP17: 정상 | AQ17: 제품 | AR17: =IF($AP17="악성",$AM17,0) -> 0 | AS17: =IF($AP17="부진",$AM17,0) -> 0 | AT17: =IF($AP17="정상",$AM17,0) -> 1292027 | AU17: =SUM(AR17:AT17) -> 1292027 | AV17: =IF(+BB17*$AL17=0,"",+BB17*$AL17) -> 1292027.9 | AW17: =IF(+BC17*$AL17=0,"",+BC17*$AL17) | AX17: =IF(+BD17*$AL17=0,"",+BD17*$AL17) | AY17: =IF(+BE17*$AL17=0,"",+BE17*$AL17) | AZ17: =IF(+BF17*$AL17=0,"",+BF17*$AL17) | BB17: 203 | BC17: 0 | BD17: 0 | BE17: 0 | BF17: 0 | BG17: =+SUM(BB17:BF17) -> 203 | BH17: =BG17-AK17 -> 0 | BI17: =IFERROR(IF(ROUND(V17/((D17+AK17)/2),1)<0,0,ROUND(V17/((D17+AK17)/2),1)),0) -> 3.4 | BJ17: =IF(AK17=0,"정상",IF(AP17="악성","악성",IF(AND(BL17>3,BI17<0.5),"악성",IF(AND(AP17="정상",BL17<=3),"정상",IF(BI17>1,"정상","부진"))))) -> 정상 | BK17: 45992 | BL17: =DATEDIF(BK17,$BL$9,"m")+1 -> 10
A18: 제품 | B18: DCP125001 | C18: 데코데코 포장의 달인 | D18: 1541 | E18: 2456.7868 | F18: 3785908 | G18: 0 | H18: 0 | I18: 0 | J18: 4800 | K18: 2465.5 | L18: 11834400 | M18: 1 | N18: 2464 | O18: 2464 | P18: 0 | Q18: 0 | R18: 0 | S18: 4801 | T18: 2465.4997 | U18: 11836864 | V18: 5599 | W18: 2463.2127 | X18: 13791528 | Y18: 0 | Z18: 0 | AA18: 0 | AB18: 32 | AC18: 2464.375 | AD18: 78860 | AE18: 0 | AF18: 0 | AG18: 0 | AH18: 5631 | AI18: 2463.2193 | AJ18: 13870388 | AK18: 711 | AL18: 2464.6762 | AM18: 1752384 | AN18: =AM18/$AM$4 -> 0.00016583532 | AO18: =IF(ISERROR(AK18/(D18+S18)),,(AK18/(D18+S18))) -> 0.11210974 | AP18: 정상 | AQ18: 제품 | AR18: =IF($AP18="악성",$AM18,0) -> 0 | AS18: =IF($AP18="부진",$AM18,0) -> 0 | AT18: =IF($AP18="정상",$AM18,0) -> 1752384 | AU18: =SUM(AR18:AT18) -> 1752384 | AV18: =IF(+BB18*$AL18=0,"",+BB18*$AL18) -> 1752384.8 | AW18: =IF(+BC18*$AL18=0,"",+BC18*$AL18) | AX18: =IF(+BD18*$AL18=0,"",+BD18*$AL18) | AY18: =IF(+BE18*$AL18=0,"",+BE18*$AL18) | AZ18: =IF(+BF18*$AL18=0,"",+BF18*$AL18) | BB18: 711 | BC18: 0 | BD18: 0 | BE18: 0 | BF18: 0 | BG18: =+SUM(BB18:BF18) -> 711 | BH18: =BG18-AK18 -> 0 | BI18: =IFERROR(IF(ROUND(V18/((D18+AK18)/2),1)<0,0,ROUND(V18/((D18+AK18)/2),1)),0) -> 5 | BJ18: =IF(AK18=0,"정상",IF(AP18="악성","악성",IF(AND(BL18>3,BI18<0.5),"악성",IF(AND(AP18="정상",BL18<=3),"정상",IF(BI18>1,"정상","부진"))))) -> 정상 | BK18: 45901 | BL18: =DATEDIF(BK18,$BL$9,"m")+1 -> 13
A19: 제품 | B19: DCP125002 | C19: 데코데코 말캉말캉 디저트 스퀴시북 | D19: 0 | E19: 0 | F19: 0 | G19: 0 | H19: 0 | I19: 0 | J19: 6000 | K19: 3457.9397 | L19: 20747638 | M19: 72 | N19: 1 | O19: 72 | P19: 0 | Q19: 0 | R19: 0 | S19: 6072 | T19: 3416.9483 | U19: 20747710 | V19: 4226 | W19: 3420.5372 | X19: 14455190 | Y19: 0 | Z19: 0 | AA19: 0 | AB19: 32 | AC19: 3428.2812 | AD19: 109705 | AE19: 0 | AF19: 0 | AG19: 0 | AH19: 4258 | AI19: 3420.5953 | AJ19: 14564895 | AK19: 1814 | AL19: 3408.3878 | AM19: 6182815 | AN19: =AM19/$AM$4 -> 0.00058510526 | AO19: =IF(ISERROR(AK19/(D19+S19)),,(AK19/(D19+S19))) -> 0.29874835 | AP19: 정상 | AQ19: 제품 | AR19: =IF($AP19="악성",$AM19,0) -> 0 | AS19: =IF($AP19="부진",$AM19,0) -> 0 | AT19: =IF($AP19="정상",$AM19,0) -> 6182815 | AU19: =SUM(AR19:AT19) -> 6182815 | AV19: =IF(+BB19*$AL19=0,"",+BB19*$AL19) -> 6182815.5 | AW19: =IF(+BC19*$AL19=0,"",+BC19*$AL19) | AX19: =IF(+BD19*$AL19=0,"",+BD19*$AL19) | AY19: =IF(+BE19*$AL19=0,"",+BE19*$AL19) | AZ19: =IF(+BF19*$AL19=0,"",+BF19*$AL19) | BB19: 1814 | BC19: 0 | BD19: 0 | BE19: 0 | BF19: 0 | BG19: =+SUM(BB19:BF19) -> 1814 | BH19: =BG19-AK19 -> 0 | BI19: =IFERROR(IF(ROUND(V19/((D19+AK19)/2),1)<0,0,ROUND(V19/((D19+AK19)/2),1)),0) -> 4.7 | BJ19: =IF(AK19=0,"정상",IF(AP19="악성","악성",IF(AND(BL19>3,BI19<0.5),"악성",IF(AND(AP19="정상",BL19<=3),"정상",IF(BI19>1,"정상","부진"))))) -> 정상 | BK19: 46082 | BL19: =DATEDIF(BK19,$BL$9,"m")+1 -> 7
A20: 제품 | B20: DCT122001 | C20: 데코데코 말캉이 메이킷 | D20: 681 | E20: 14162.982 | F20: 9644990 | G20: 41526 | H20: 14527.766 | I20: 603280024 | J20: 0 | K20: 0 | L20: 0 | M20: 13 | N20: 14376 | O20: 186888 | P20: 0 | Q20: 0 | R20: 0 | S20: 41539 | T20: 14527.719 | U20: 603466912 | V20: 38978 | W20: 14482.375 | X20: 564494002 | Y20: 0 | Z20: 0 | AA20: 0 | AB20: 78 | AC20: 14508.885 | AD20: 1131693 | AE20: 0 | AF20: 0 | AG20: 0 | AH20: 39056 | AI20: 14482.428 | AJ20: 565625695 | AK20: 3164 | AL20: 15008.283 | AM20: 47486207 | AN20: =AM20/$AM$4 -> 0.0044938155 | AO20: =IF(ISERROR(AK20/(D20+S20)),,(AK20/(D20+S20))) -> 0.074940786 | AP20: 정상 | AQ20: 제품 | AR20: =IF($AP20="악성",$AM20,0) -> 0 | AS20: =IF($AP20="부진",$AM20,0) -> 0 | AT20: =IF($AP20="정상",$AM20,0) -> 47486207 | AU20: =SUM(AR20:AT20) -> 47486207 | AV20: =IF(+BB20*$AL20=0,"",+BB20*$AL20) -> 47486208 | AW20: =IF(+BC20*$AL20=0,"",+BC20*$AL20) | AX20: =IF(+BD20*$AL20=0,"",+BD20*$AL20) | AY20: =IF(+BE20*$AL20=0,"",+BE20*$AL20) | AZ20: =IF(+BF20*$AL20=0,"",+BF20*$AL20) | BB20: 3164 | BC20: 0 | BD20: 0 | BE20: 0 | BF20: 0 | BG20: =+SUM(BB20:BF20) -> 3164 | BH20: =BG20-AK20 -> 0 | BI20: =IFERROR(IF(ROUND(V20/((D20+AK20)/2),1)<0,0,ROUND(V20/((D20+AK20)/2),1)),0) -> 20.3 | BJ20: =IF(AK20=0,"정상",IF(AP20="악성","악성",IF(AND(BL20>3,BI20<0.5),"악성",IF(AND(AP20="정상",BL20<=3),"정상",IF(BI20>1,"정상","부진"))))) -> 정상 | BK20: 46204 | BL20: =DATEDIF(BK20,$BL$9,"m")+1 -> 3
A21: 제품 | B21: DCT122002 | C21: 데코데코 말캉이 메이킷 - 디저트 키트 | D21: 3015 | E21: 7060.0336 | F21: 21286001 | G21: 5000 | H21: 7037.124 | I21: 35185620 | J21: 0 | K21: 0 | L21: 0 | M21: 5 | N21: 7046 | O21: 35230 | P21: 0 | Q21: 0 | R21: 0 | S21: 5005 | T21: 7037.1329 | U21: 35220850 | V21: 7385 | W21: 7045.7418 | X21: 52032803 | Y21: 0 | Z21: 0 | AA21: 0 | AB21: 37 | AC21: 7045.8649 | AD21: 260697 | AE21: 0 | AF21: 0 | AG21: 0 | AH21: 7422 | AI21: 7045.7424 | AJ21: 52293500 | AK21: 598 | AL21: 7045.7388 | AM21: 4213351 | AN21: =AM21/$AM$4 -> 0.00039872677 | AO21: =IF(ISERROR(AK21/(D21+S21)),,(AK21/(D21+S21))) -> 0.074563591 | AP21: 정상 | AQ21: 제품 | AR21: =IF($AP21="악성",$AM21,0) -> 0 | AS21: =IF($AP21="부진",$AM21,0) -> 0 | AT21: =IF($AP21="정상",$AM21,0) -> 4213351 | AU21: =SUM(AR21:AT21) -> 4213351 | AV21: =IF(+BB21*$AL21=0,"",+BB21*$AL21) -> 4213351.8 | AW21: =IF(+BC21*$AL21=0,"",+BC21*$AL21) | AX21: =IF(+BD21*$AL21=0,"",+BD21*$AL21) | AY21: =IF(+BE21*$AL21=0,"",+BE21*$AL21) | AZ21: =IF(+BF21*$AL21=0,"",+BF21*$AL21) | BB21: 598 | BC21: 0 | BD21: 0 | BE21: 0 | BF21: 0 | BG21: =+SUM(BB21:BF21) -> 598 | BH21: =BG21-AK21 -> 0 | BI21: =IFERROR(IF(ROUND(V21/((D21+AK21)/2),1)<0,0,ROUND(V21/((D21+AK21)/2),1)),0) -> 4.1 | BJ21: =IF(AK21=0,"정상",IF(AP21="악성","악성",IF(AND(BL21>3,BI21<0.5),"악성",IF(AND(AP21="정상",BL21<=3),"정상",IF(BI21>1,"정상","부진"))))) -> 정상 | BK21: 44835 | BL21: =DATEDIF(BK21,$BL$9,"m")+1 -> 48
A22: 제품 | B22: DCT122003 | C22: 데코데코 말캉이 메이킷 - 아이스크림 키트 | D22: 7732 | E22: 5390.335 | F22: 41678069 | G22: 4000 | H22: 5693.9788 | I22: 22775915 | J22: 0 | K22: 0 | L22: 0 | M22: 5 | N22: 5390 | O22: 26950 | P22: 0 | Q22: 0 | R22: 0 | S22: 4005 | T22: 5693.5993 | U22: 22802865 | V22: 8906 | W22: 5456.019 | X22: 48591305 | Y22: 0 | Z22: 0 | AA22: 0 | AB22: 25 | AC22: 5417.48 | AD22: 135437 | AE22: 0 | AF22: 0 | AG22: 0 | AH22: 8931 | AI22: 5455.9111 | AJ22: 48726742 | AK22: 2806 | AL22: 5614.4662 | AM22: 15754192 | AN22: =AM22/$AM$4 -> 0.0014908841 | AO22: =IF(ISERROR(AK22/(D22+S22)),,(AK22/(D22+S22))) -> 0.23907302 | AP22: 정상 | AQ22: =A22 -> 제품 | AR22: =IF($AP22="악성",$AM22,0) -> 0 | AS22: =IF($AP22="부진",$AM22,0) -> 0 | AT22: =IF($AP22="정상",$AM22,0) -> 15754192 | AU22: =SUM(AR22:AT22) -> 15754192 | AV22: =IF(+BB22*$AL22=0,"",+BB22*$AL22) -> 15754192 | AW22: =IF(+BC22*$AL22=0,"",+BC22*$AL22) | AX22: =IF(+BD22*$AL22=0,"",+BD22*$AL22) | AY22: =IF(+BE22*$AL22=0,"",+BE22*$AL22) | AZ22: =IF(+BF22*$AL22=0,"",+BF22*$AL22) | BB22: 2806 | BC22: 0 | BD22: 0 | BE22: 0 | BF22: 0 | BG22: =+SUM(BB22:BF22) -> 2806 | BH22: =BG22-AK22 -> 0 | BI22: =IFERROR(IF(ROUND(V22/((D22+AK22)/2),1)<0,0,ROUND(V22/((D22+AK22)/2),1)),0) -> 1.7 | BJ22: =IF(AK22=0,"정상",IF(AP22="악성","악성",IF(AND(BL22>3,BI22<0.5),"악성",IF(AND(AP22="정상",BL22<=3),"정상",IF(BI22>1,"정상","부진"))))) -> 정상 | BK22: 46204 | BL22: =DATEDIF(BK22,$BL$9,"m")+1 -> 3
A23: 제품 | B23: DCT122004 | C23: 데코데코 시크릿 캐비닛 러블리 핑크 | D23: 2890 | E23: 11929.933 | F23: 34477507 | G23: 10000 | H23: 12563.789 | I23: 125637886 | J23: 0 | K23: 0 | L23: 0 | M23: 2 | N23: 12339 | O23: 24678 | P23: 0 | Q23: 0 | R23: 0 | S23: 10002 | T23: 12563.744 | U23: 125662564 | V23: 8641 | W23: 12139.947 | X23: 104901282 | Y23: 0 | Z23: 0 | AA23: 0 | AB23: 25 | AC23: 12469.64 | AD23: 311741 | AE23: 0 | AF23: 0 | AG23: 0 | AH23: 8666 | AI23: 12140.898 | AJ23: 105213023 | AK23: 4226 | AL23: 12997.409 | AM23: 54927048 | AN23: =AM23/$AM$4 -> 0.0051979729 | AO23: =IF(ISERROR(AK23/(D23+S23)),,(AK23/(D23+S23))) -> 0.32780019 | AP23: 정상 | AQ23: =A23 -> 제품 | AR23: =IF($AP23="악성",$AM23,0) -> 0 | AS23: =IF($AP23="부진",$AM23,0) -> 0 | AT23: =IF($AP23="정상",$AM23,0) -> 54927048 | AU23: =SUM(AR23:AT23) -> 54927048 | AV23: =IF(+BB23*$AL23=0,"",+BB23*$AL23) -> 54927049 | AW23: =IF(+BC23*$AL23=0,"",+BC23*$AL23) | AX23: =IF(+BD23*$AL23=0,"",+BD23*$AL23) | AY23: =IF(+BE23*$AL23=0,"",+BE23*$AL23) | AZ23: =IF(+BF23*$AL23=0,"",+BF23*$AL23) | BB23: 4226 | BC23: 0 | BD23: 0 | BE23: 0 | BF23: 0 | BG23: =+SUM(BB23:BF23) -> 4226 | BH23: =BG23-AK23 -> 0 | BI23: =IFERROR(IF(ROUND(V23/((D23+AK23)/2),1)<0,0,ROUND(V23/((D23+AK23)/2),1)),0) -> 2.4 | BJ23: =IF(AK23=0,"정상",IF(AP23="악성","악성",IF(AND(BL23>3,BI23<0.5),"악성",IF(AND(AP23="정상",BL23<=3),"정상",IF(BI23>1,"정상","부진"))))) -> 정상 | BK23: 46174 | BL23: =DATEDIF(BK23,$BL$9,"m")+1 -> 4
A24: 제품 | B24: DCT122005 | C24: 데코데코 시크릿 캐비닛 트렌디 퍼플 | D24: 883 | E24: 11559.003 | F24: 10206598 | G24: 8000 | H24: 12349.793 | I24: 98798342 | J24: 0 | K24: 0 | L24: 0 | M24: 15 | N24: 12001.133 | O24: 180017 | P24: 0 | Q24: 0 | R24: 0 | S24: 8015 | T24: 12349.14 | U24: 98978359 | V24: 5474 | W24: 11978.408 | X24: 65569804 | Y24: 0 | Z24: 0 | AA24: 0 | AB24: 33 | AC24: 12010.939 | AD24: 396361 | AE24: 0 | AF24: 0 | AG24: 0 | AH24: 5507 | AI24: 11978.603 | AJ24: 65966165 | AK24: 3391 | AL24: 12745.147 | AM24: 43218792 | AN24: =AM24/$AM$4 -> 0.0040899724 | AO24: =IF(ISERROR(AK24/(D24+S24)),,(AK24/(D24+S24))) -> 0.38109688 | AP24: 정상 | AQ24: =A24 -> 제품 | AR24: =IF($AP24="악성",$AM24,0) -> 0 | AS24: =IF($AP24="부진",$AM24,0) -> 0 | AT24: =IF($AP24="정상",$AM24,0) -> 43218792 | AU24: =SUM(AR24:AT24) -> 43218792 | AV24: =IF(+BB24*$AL24=0,"",+BB24*$AL24) -> 43218793 | AW24: =IF(+BC24*$AL24=0,"",+BC24*$AL24) | AX24: =IF(+BD24*$AL24=0,"",+BD24*$AL24) | AY24: =IF(+BE24*$AL24=0,"",+BE24*$AL24) | AZ24: =IF(+BF24*$AL24=0,"",+BF24*$AL24) | BB24: 3391 | BC24: 0 | BD24: 0 | BE24: 0 | BF24: 0 | BG24: =+SUM(BB24:BF24) -> 3391 | BH24: =BG24-AK24 -> 0 | BI24: =IFERROR(IF(ROUND(V24/((D24+AK24)/2),1)<0,0,ROUND(V24/((D24+AK24)/2),1)),0) -> 2.6 | BJ24: =IF(AK24=0,"정상",IF(AP24="악성","악성",IF(AND(BL24>3,BI24<0.5),"악성",IF(AND(AP24="정상",BL24<=3),"정상",IF(BI24>1,"정상","부진"))))) -> 정상 | BK24: 46235 | BL24: =DATEDIF(BK24,$BL$9,"m")+1 -> 2
A25: 제품 | B25: DCT122006 | C25: 데코데코 유니콘 라떼 글리터 슬라임 만들기 | D25: 6818 | E25: 5055.3696 | F25: 34467510 | G25: 0 | H25: 0 | I25: 0 | J25: 10000 | K25: 4910.1613 | L25: 49101613 | M25: 0 | N25: 0 | O25: 0 | P25: 0 | Q25: 0 | R25: 0 | S25: 10000 | T25: 4910.1613 | U25: 49101613 | V25: 14018 | W25: 4948.4538 | X25: 69367426 | Y25: 0 | Z25: 0 | AA25: 0 | AB25: 38 | AC25: 4953.1579 | AD25: 188220 | AE25: 0 | AF25: 0 | AG25: 0 | AH25: 14056 | AI25: 4948.4666 | AJ25: 69555646 | AK25: 2762 | AL25: 5073.6702 | AM25: 14013477 | AN25: =AM25/$AM$4 -> 0.0013261531 | AO25: =IF(ISERROR(AK25/(D25+S25)),,(AK25/(D25+S25))) -> 0.1642288 | AP25: 정상 | AQ25: =A25 -> 제품 | AR25: =IF($AP25="악성",$AM25,0) -> 0 | AS25: =IF($AP25="부진",$AM25,0) -> 0 | AT25: =IF($AP25="정상",$AM25,0) -> 14013477 | AU25: =SUM(AR25:AT25) -> 14013477 | AV25: =IF(+BB25*$AL25=0,"",+BB25*$AL25) -> 14013477 | AW25: =IF(+BC25*$AL25=0,"",+BC25*$AL25) | AX25: =IF(+BD25*$AL25=0,"",+BD25*$AL25) | AY25: =IF(+BE25*$AL25=0,"",+BE25*$AL25) | AZ25: =IF(+BF25*$AL25=0,"",+BF25*$AL25) | BB25: 2762 | BC25: 0 | BD25: 0 | BE25: 0 | BF25: 0 | BG25: =+SUM(BB25:BF25) -> 2762 | BH25: =BG25-AK25 -> 0 | BI25: =IFERROR(IF(ROUND(V25/((D25+AK25)/2),1)<0,0,ROUND(V25/((D25+AK25)/2),1)),0) -> 2.9 | BJ25: =IF(AK25=0,"정상",IF(AP25="악성","악성",IF(AND(BL25>3,BI25<0.5),"악성",IF(AND(AP25="정상",BL25<=3),"정상",IF(BI25>1,"정상","부진"))))) -> 정상 | BK25: 45809 | BL25: =DATEDIF(BK25,$BL$9,"m")+1 -> 16
A26: 제품 | B26: DCT122008 | C26: 데코데코 달콤 디저트 슈링클스 키링 만들기 | D26: 651 | E26: 4520.2068 | F26: 2942654 | G26: 0 | H26: 0 | I26: 0 | J26: 0 | K26: 0 | L26: 0 | M26: 0 | N26: 0 | O26: 0 | P26: 0 | Q26: 0 | R26: 0 | S26: 0 | T26: 0 | U26: 0 | V26: 583 | W26: 4520.211 | X26: 2635283 | Y26: 0 | Z26: 0 | AA26: 0 | AB26: 1 | AC26: 4521 | AD26: 4521 | AE26: 0 | AF26: 0 | AG26: 0 | AH26: 584 | AI26: 4520.2123 | AJ26: 2639804 | AK26: 67 | AL26: 4520.1594 | AM26: 302850 | AN26: =AM26/$AM$4 -> 2.8659944e-05 | AO26: =IF(ISERROR(AK26/(D26+S26)),,(AK26/(D26+S26))) -> 0.10291859 | AP26: 부진 | AQ26: =A26 -> 제품 | AR26: =IF($AP26="악성",$AM26,0) -> 0 | AS26: =IF($AP26="부진",$AM26,0) -> 302850 | AT26: =IF($AP26="정상",$AM26,0) -> 0 | AU26: =SUM(AR26:AT26) -> 302850 | AV26: =IF(+BB26*$AL26=0,"",+BB26*$AL26) -> 302850.68 | AW26: =IF(+BC26*$AL26=0,"",+BC26*$AL26) | AX26: =IF(+BD26*$AL26=0,"",+BD26*$AL26) | AY26: =IF(+BE26*$AL26=0,"",+BE26*$AL26) | AZ26: =IF(+BF26*$AL26=0,"",+BF26*$AL26) | BB26: 67 | BC26: 0 | BD26: 0 | BE26: 0 | BF26: 0 | BG26: =+SUM(BB26:BF26) -> 67 | BH26: =BG26-AK26 -> 0 | BI26: =IFERROR(IF(ROUND(V26/((D26+AK26)/2),1)<0,0,ROUND(V26/((D26+AK26)/2),1)),0) -> 1.6 | BJ26: =IF(AK26=0,"정상",IF(AP26="악성","악성",IF(AND(BL26>3,BI26<0.5),"악성",IF(AND(AP26="정상",BL26<=3),"정상",IF(BI26>1,"정상","부진"))))) -> 정상 | BK26: 44805 | BL26: =DATEDIF(BK26,$BL$9,"m")+1 -> 49
A27: 제품 | B27: DCT122009 | C27: 데코데코 냠냠파티 디폼블럭 만들기 | D27: 1370 | E27: 2561.8491 | F27: 3509733 | G27: 0 | H27: 0 | I27: 0 | J27: 0 | K27: 0 | L27: 0 | M27: 3 | N27: 2562 | O27: 7686 | P27: 0 | Q27: 0 | R27: 0 | S27: 3 | T27: 2562 | U27: 7686 | V27: 1097 | W27: 2561.8532 | X27: 2810353 | Y27: 0 | Z27: 0 | AA27: 0 | AB27: 9 | AC27: 2562 | AD27: 23058 | AE27: 0 | AF27: 0 | AG27: 0 | AH27: 1106 | AI27: 2561.8544 | AJ27: 2833411 | AK27: 267 | AL27: 2561.8303 | AM27: 684008 | AN27: =AM27/$AM$4 -> 6.4730496e-05 | AO27: =IF(ISERROR(AK27/(D27+S27)),,(AK27/(D27+S27))) -> 0.19446468 | AP27: 부진 | AQ27: =A27 -> 제품 | AR27: =IF($AP27="악성",$AM27,0) -> 0 | AS27: =IF($AP27="부진",$AM27,0) -> 684008 | AT27: =IF($AP27="정상",$AM27,0) -> 0 | AU27: =SUM(AR27:AT27) -> 684008 | AV27: =IF(+BB27*$AL27=0,"",+BB27*$AL27) -> 684008.69 | AW27: =IF(+BC27*$AL27=0,"",+BC27*$AL27) | AX27: =IF(+BD27*$AL27=0,"",+BD27*$AL27) | AY27: =IF(+BE27*$AL27=0,"",+BE27*$AL27) | AZ27: =IF(+BF27*$AL27=0,"",+BF27*$AL27) | BB27: 267 | BC27: 0 | BD27: 0 | BE27: 0 | BF27: 0 | BG27: =+SUM(BB27:BF27) -> 267 | BH27: =BG27-AK27 -> 0 | BI27: =IFERROR(IF(ROUND(V27/((D27+AK27)/2),1)<0,0,ROUND(V27/((D27+AK27)/2),1)),0) -> 1.3 | BJ27: =IF(AK27=0,"정상",IF(AP27="악성","악성",IF(AND(BL27>3,BI27<0.5),"악성",IF(AND(AP27="정상",BL27<=3),"정상",IF(BI27>1,"정상","부진"))))) -> 정상 | BK27: 44835 | BL27: =DATEDIF(BK27,$BL$9,"m")+1 -> 48
A28: 제품 | B28: DCT123001 | C28: 데코데코 롤링 스티커펜 디럭스 다꾸 키트 | D28: 2703 | E28: 11716.273 | F28: 31669085 | G28: 0 | H28: 0 | I28: 0 | J28: 0 | K28: 0 | L28: 0 | M28: 1 | N28: 11716 | O28: 11716 | P28: 0 | Q28: 0 | R28: 0 | S28: 1 | T28: 11716 | U28: 11716 | V28: 2190 | W28: 11716.275 | X28: 25658642 | Y28: 0 | Z28: 0 | AA28: 0 | AB28: 38 | AC28: 11716.368 | AD28: 445222 | AE28: 0 | AF28: 0 | AG28: 0 | AH28: 2228 | AI28: 11716.276 | AJ28: 26103864 | AK28: 476 | AL28: 11716.256 | AM28: 5576937 | AN28: =AM28/$AM$4 -> 0.00052776853 | AO28: =IF(ISERROR(AK28/(D28+S28)),,(AK28/(D28+S28))) -> 0.1760355 | AP28: 부진 | AQ28: =A28 -> 제품 | AR28: =IF($AP28="악성",$AM28,0) -> 0 | AS28: =IF($AP28="부진",$AM28,0) -> 5576937 | AT28: =IF($AP28="정상",$AM28,0) -> 0 | AU28: =SUM(AR28:AT28) -> 5576937 | AV28: =IF(+BB28*$AL28=0,"",+BB28*$AL28) -> 5576937.7 | AW28: =IF(+BC28*$AL28=0,"",+BC28*$AL28) | AX28: =IF(+BD28*$AL28=0,"",+BD28*$AL28) | AY28: =IF(+BE28*$AL28=0,"",+BE28*$AL28) | AZ28: =IF(+BF28*$AL28=0,"",+BF28*$AL28) | BB28: 476 | BC28: 0 | BD28: 0 | BE28: 0 | BF28: 0 | BG28: =+SUM(BB28:BF28) -> 476 | BH28: =BG28-AK28 -> 0 | BI28: =IFERROR(IF(ROUND(V28/((D28+AK28)/2),1)<0,0,ROUND(V28/((D28+AK28)/2),1)),0) -> 1.4 | BJ28: =IF(AK28=0,"정상",IF(AP28="악성","악성",IF(AND(BL28>3,BI28<0.5),"악성",IF(AND(AP28="정상",BL28<=3),"정상",IF(BI28>1,"정상","부진"))))) -> 정상 | BK28: 44986 | BL28: =DATEDIF(BK28,$BL$9,"m")+1 -> 43
A29: 제품 | B29: DCT123002 | C29: 데코데코 롤링 스티커펜 샤이니 키트 | D29: 7361 | E29: 6015.5166 | F29: 44280218 | G29: 0 | H29: 0 | I29: 0 | J29: 0 | K29: 0 | L29: 0 | M29: 0 | N29: 0 | O29: 0 | P29: 0 | Q29: 0 | R29: 0 | S29: 0 | T29: 0 | U29: 0 | V29: 3077 | W29: 6015.518 | X29: 18509749 | Y29: 0 | Z29: 0 | AA29: 0 | AB29: 1521 | AC29: 6015.5194 | AD29: 9149605 | AE29: 0 | AF29: 0 | AG29: 0 | AH29: 4598 | AI29: 6015.5185 | AJ29: 27659354 | AK29: 2763 | AL29: 6015.5135 | AM29: 16620864 | AN29: =AM29/$AM$4 -> 0.0015729009 | AO29: =IF(ISERROR(AK29/(D29+S29)),,(AK29/(D29+S29))) -> 0.37535661 | AP29: 부진 | AQ29: =A29 -> 제품 | AR29: =IF($AP29="악성",$AM29,0) -> 0 | AS29: =IF($AP29="부진",$AM29,0) -> 16620864 | AT29: =IF($AP29="정상",$AM29,0) -> 0 | AU29: =SUM(AR29:AT29) -> 16620864 | AV29: =IF(+BB29*$AL29=0,"",+BB29*$AL29) -> 16620864 | AW29: =IF(+BC29*$AL29=0,"",+BC29*$AL29) | AX29: =IF(+BD29*$AL29=0,"",+BD29*$AL29) | AY29: =IF(+BE29*$AL29=0,"",+BE29*$AL29) | AZ29: =IF(+BF29*$AL29=0,"",+BF29*$AL29) | BB29: 2763 | BC29: 0 | BD29: 0 | BE29: 0 | BF29: 0 | BG29: =+SUM(BB29:BF29) -> 2763 | BH29: =BG29-AK29 -> 0 | BI29: =IFERROR(IF(ROUND(V29/((D29+AK29)/2),1)<0,0,ROUND(V29/((D29+AK29)/2),1)),0) -> 0.6 | BJ29: =IF(AK29=0,"정상",IF(AP29="악성","악성",IF(AND(BL29>3,BI29<0.5),"악성",IF(AND(AP29="정상",BL29<=3),"정상",IF(BI29>1,"정상","부진"))))) -> 부진 | BK29: 44986 | BL29: =DATEDIF(BK29,$BL$9,"m")+1 -> 43
A30: 제품 | B30: DCT123003 | C30: 데코데코 롤링 스티커펜 코튼캔디 키트 | D30: 5485 | E30: 5362.1402 | F30: 29411339 | G30: 0 | H30: 0 | I30: 0 | J30: 0 | K30: 0 | L30: 0 | M30: 0 | N30: 0 | O30: 0 | P30: 0 | Q30: 0 | R30: 0 | S30: 0 | T30: 0 | U30: 0 | V30: 4413 | W30: 5362.1412 | X30: 23663129 | Y30: 0 | Z30: 0 | AA30: 0 | AB30: 35 | AC30: 5362.3143 | AD30: 187681 | AE30: 0 | AF30: 0 | AG30: 0 | AH30: 4448 | AI30: 5362.1425 | AJ30: 23850810 | AK30: 1037 | AL30: 5362.1301 | AM30: 5560529 | AN30: =AM30/$AM$4 -> 0.00052621577 | AO30: =IF(ISERROR(AK30/(D30+S30)),,(AK30/(D30+S30))) -> 0.18906108 | AP30: 부진 | AQ30: =A30 -> 제품 | AR30: =IF($AP30="악성",$AM30,0) -> 0 | AS30: =IF($AP30="부진",$AM30,0) -> 5560529 | AT30: =IF($AP30="정상",$AM30,0) -> 0 | AU30: =SUM(AR30:AT30) -> 5560529 | AV30: =IF(+BB30*$AL30=0,"",+BB30*$AL30) -> 5560528.9 | AW30: =IF(+BC30*$AL30=0,"",+BC30*$AL30) | AX30: =IF(+BD30*$AL30=0,"",+BD30*$AL30) | AY30: =IF(+BE30*$AL30=0,"",+BE30*$AL30) | AZ30: =IF(+BF30*$AL30=0,"",+BF30*$AL30) | BB30: 1037 | BC30: 0 | BD30: 0 | BE30: 0 | BF30: 0 | BG30: =+SUM(BB30:BF30) -> 1037 | BH30: =BG30-AK30 -> 0 | BI30: =IFERROR(IF(ROUND(V30/((D30+AK30)/2),1)<0,0,ROUND(V30/((D30+AK30)/2),1)),0) -> 1.4 | BJ30: =IF(AK30=0,"정상",IF(AP30="악성","악성",IF(AND(BL30>3,BI30<0.5),"악성",IF(AND(AP30="정상",BL30<=3),"정상",IF(BI30>1,"정상","부진"))))) -> 정상 | BK30: 44986 | BL30: =DATEDIF(BK30,$BL$9,"m")+1 -> 43
A31: 제품 | B31: DCT123004 | C31: 데코데코 드로잉패드 PRO - 아바타 포꾸 키트 | D31: 6850 | E31: 11801.886 | F31: 80842917 | G31: 5004 | H31: 12225.922 | I31: 61178514 | J31: 0 | K31: 0 | L31: 0 | M31: 0 | N31: 0 | O31: 0 | P31: 0 | Q31: 0 | R31: 0 | S31: 5004 | T31: 12225.922 | U31: 61178514 | V31: 6864 | W31: 11829.855 | X31: 81200125 | Y31: 0 | Z31: 0 | AA31: 0 | AB31: 14 | AC31: 11802.071 | AD31: 165229 | AE31: 0 | AF31: 0 | AG31: 0 | AH31: 6878 | AI31: 11829.798 | AJ31: 81365354 | AK31: 4976 | AL31: 12189.726 | AM31: 60656077 | AN31: =AM31/$AM$4 -> 0.0057401345 | AO31: =IF(ISERROR(AK31/(D31+S31)),,(AK31/(D31+S31))) -> 0.41977392 | AP31: 정상 | AQ31: =A31 -> 제품 | AR31: =IF($AP31="악성",$AM31,0) -> 0 | AS31: =IF($AP31="부진",$AM31,0) -> 0 | AT31: =IF($AP31="정상",$AM31,0) -> 60656077 | AU31: =SUM(AR31:AT31) -> 60656077 | AV31: =IF(+BB31*$AL31=0,"",+BB31*$AL31) -> 60656077 | AW31: =IF(+BC31*$AL31=0,"",+BC31*$AL31) | AX31: =IF(+BD31*$AL31=0,"",+BD31*$AL31) | AY31: =IF(+BE31*$AL31=0,"",+BE31*$AL31) | AZ31: =IF(+BF31*$AL31=0,"",+BF31*$AL31) | BB31: 4976 | BC31: 0 | BD31: 0 | BE31: 0 | BF31: 0 | BG31: =+SUM(BB31:BF31) -> 4976 | BH31: =BG31-AK31 -> 0 | BI31: =IFERROR(IF(ROUND(V31/((D31+AK31)/2),1)<0,0,ROUND(V31/((D31+AK31)/2),1)),0) -> 1.2 | BJ31: =IF(AK31=0,"정상",IF(AP31="악성","악성",IF(AND(BL31>3,BI31<0.5),"악성",IF(AND(AP31="정상",BL31<=3),"정상",IF(BI31>1,"정상","부진"))))) -> 정상 | BK31: 46235 | BL31: =DATEDIF(BK31,$BL$9,"m")+1 -> 2
A32: 제품 | B32: DCT123005 | C32: 데코데코 인싸젤리 메이킷 | D32: 2761 | E32: 14941.971 | F32: 41254781 | G32: 0 | H32: 0 | I32: 0 | J32: 30972 | K32: 15310.222 | L32: 474188208 | M32: 6 | N32: 15163.833 | O32: 90983 | P32: 0 | Q32: 0 | R32: 0 | S32: 30978 | T32: 15310.194 | U32: 474279191 | V32: 24458 | W32: 15218.555 | X32: 372215408 | Y32: 0 | Z32: 0 | AA32: 0 | AB32: 118 | AC32: 15224.5 | AD32: 1796491 | AE32: 0 | AF32: 0 | AG32: 0 | AH32: 24576 | AI32: 15218.583 | AJ32: 374011899 | AK32: 9163 | AL32: 15444.95 | AM32: 141522073 | AN32: =AM32/$AM$4 -> 0.013392817 | AO32: =IF(ISERROR(AK32/(D32+S32)),,(AK32/(D32+S32))) -> 0.27158481 | AP32: 정상 | AQ32: =A32 -> 제품 | AR32: =IF($AP32="악성",$AM32,0) -> 0 | AS32: =IF($AP32="부진",$AM32,0) -> 0 | AT32: =IF($AP32="정상",$AM32,0) -> 141522073 | AU32: =SUM(AR32:AT32) -> 141522073 | AV32: =IF(+BB32*$AL32=0,"",+BB32*$AL32) -> 1.4152207e+08 | AW32: =IF(+BC32*$AL32=0,"",+BC32*$AL32) | AX32: =IF(+BD32*$AL32=0,"",+BD32*$AL32) | AY32: =IF(+BE32*$AL32=0,"",+BE32*$AL32) | AZ32: =IF(+BF32*$AL32=0,"",+BF32*$AL32) | BB32: 9163 | BC32: 0 | BD32: 0 | BE32: 0 | BF32: 0 | BG32: =+SUM(BB32:BF32) -> 9163 | BH32: =BG32-AK32 -> 0 | BI32: =IFERROR(IF(ROUND(V32/((D32+AK32)/2),1)<0,0,ROUND(V32/((D32+AK32)/2),1)),0) -> 4.1 | BJ32: =IF(AK32=0,"정상",IF(AP32="악성","악성",IF(AND(BL32>3,BI32<0.5),"악성",IF(AND(AP32="정상",BL32<=3),"정상",IF(BI32>1,"정상","부진"))))) -> 정상 | BK32: 46266 | BL32: =DATEDIF(BK32,$BL$9,"m")+1 -> 1
A33: 제품 | B33: DCT123006 | C33: 데코데코 인싸젤리 메이킷 - 과자 키트 | D33: 619 | E33: 10010.625 | F33: 6196576 | G33: 0 | H33: 0 | I33: 0 | J33: 42000 | K33: 9991.917 | L33: 419660512 | M33: 30 | N33: 9980.9333 | O33: 299428 | P33: 0 | Q33: 0 | R33: 0 | S33: 42030 | T33: 9991.9091 | U33: 419959940 | V33: 36570 | W33: 9976.4419 | X33: 364838480 | Y33: 0 | Z33: 0 | AA33: 0 | AB33: 45 | AC33: 9991.4889 | AD33: 449617 | AE33: 0 | AF33: 0 | AG33: 0 | AH33: 36615 | AI33: 9976.4604 | AJ33: 365288097 | AK33: 6034 | AL33: 10087.574 | AM33: 60868419 | AN33: =AM33/$AM$4 -> 0.0057602293 | AO33: =IF(ISERROR(AK33/(D33+S33)),,(AK33/(D33+S33))) -> 0.14148046 | AP33: 정상 | AQ33: =A33 -> 제품 | AR33: =IF($AP33="악성",$AM33,0) -> 0 | AS33: =IF($AP33="부진",$AM33,0) -> 0 | AT33: =IF($AP33="정상",$AM33,0) -> 60868419 | AU33: =SUM(AR33:AT33) -> 60868419 | AV33: =IF(+BB33*$AL33=0,"",+BB33*$AL33) -> 60868420 | AW33: =IF(+BC33*$AL33=0,"",+BC33*$AL33) | AX33: =IF(+BD33*$AL33=0,"",+BD33*$AL33) | AY33: =IF(+BE33*$AL33=0,"",+BE33*$AL33) | AZ33: =IF(+BF33*$AL33=0,"",+BF33*$AL33) | BB33: 6034 | BC33: 0 | BD33: 0 | BE33: 0 | BF33: 0 | BG33: =+SUM(BB33:BF33) -> 6034 | BH33: =BG33-AK33 -> 0 | BI33: =IFERROR(IF(ROUND(V33/((D33+AK33)/2),1)<0,0,ROUND(V33/((D33+AK33)/2),1)),0) -> 11 | BJ33: =IF(AK33=0,"정상",IF(AP33="악성","악성",IF(AND(BL33>3,BI33<0.5),"악성",IF(AND(AP33="정상",BL33<=3),"정상",IF(BI33>1,"정상","부진"))))) -> 정상 | BK33: 46266 | BL33: =DATEDIF(BK33,$BL$9,"m")+1 -> 1
... A38: 제품 | B38: DCT124003 | C38: 데코데코 알바의 달인-버거하우스 | D38: 3649 | E38: 7438.4834 | F38: 27143025 | G38: 5000 | H38: 7257.324 | I38: 36286620 | J38: 0 | K38: 0 | L38: 0 | M38: 4 | N38: 7521.75 | O38: 30087 | P38: 0 | Q38: 0 | R38: 0 | S38: 5004 | T38: 7257.5354 | U38: 36316707 | V38: 7762 | W38: 7335.5486 | X38: 56938528 | Y38: 0 | Z38: 0 | AA38: 0 | AB38: 46 | AC38: 7349.1304 | AD38: 338060 | AE38: 0 | AF38: 0 | AG38: 0 | AH38: 7808 | AI38: 7335.6286 | AJ38: 57276588 | AK38: 845 | AL38: 7317.3308 | AM38: 6183144 | AN38: =AM38/$AM$4 -> 0.0005851364 | AO38: =IF(ISERROR(AK38/(D38+S38)),,(AK38/(D38+S38))) -> 0.097653993 | AP38: 정상 | AQ38: =A38 -> 제품 | AR38: =IF($AP38="악성",$AM38,0) -> 0 | AS38: =IF($AP38="부진",$AM38,0) -> 0 | AT38: =IF($AP38="정상",$AM38,0) -> 6183144 | AU38: =SUM(AR38:AT38) -> 6183144 | AV38: =IF(+BB38*$AL38=0,"",+BB38*$AL38) -> 6183144.5 | AW38: =IF(+BC38*$AL38=0,"",+BC38*$AL38) | AX38: =IF(+BD38*$AL38=0,"",+BD38*$AL38) | AY38: =IF(+BE38*$AL38=0,"",+BE38*$AL38) | AZ38: =IF(+BF38*$AL38=0,"",+BF38*$AL38) | BB38: 845 | BC38: 0 | BD38: 0 | BE38: 0 | BF38: 0 | BG38: =+SUM(BB38:BF38) -> 845 | BH38: =BG38-AK38 -> 0 | BI38: =IFERROR(IF(ROUND(V38/((D38+AK38)/2),1)<0,0,ROUND(V38/((D38+AK38)/2),1)),0) -> 3.5 | BJ38: =IF(AK38=0,"정상",IF(AP38="악성","악성",IF(AND(BL38>3,BI38<0.5),"악성",IF(AND(AP38="정상",BL38<=3),"정상",IF(BI38>1,"정상","부진"))))) -> 정상 | BK38: 45809 | BL38: =DATEDIF(BK38,$BL$9,"m")+1 -> 16
